Workbook

Sheet データ
A1: フラジリティ曲線のパラメータ（黒田(2024) 博士論文 表3-9）
A2: 被害モードk以上となる確率 P(X≧k | 浸水深h) = Φ( (ln h − μk) / σ ) （h：浸水深[cm]、Φ：標準正規分布の累積分布関数）
A4: パラメータ | B4: 製造業 | C4: 生活関連型産業 | D4: 基礎素材型産業 | E4: 非製造業 | F4: 卸売・小売業 | G4: サービス業
A5: μ1 | B5: 3.16 | C5: 3.49 | D5: 2.72 | E5: 2.27 | F5: 2.05 | G5: -0.08
A6: μ2 | B6: 5.09 | C6: 5 | D6: 4.99 | E6: 4.76 | F6: 4.04 | G6: 4.46
A7: μ3 | B7: 6.04 | C7: 6.32 | D7: 5.59 | E7: 5.73 | F7: 5.06 | G7: 6.22
A8: μ4 | B8: － | C8: － | D8: － | E8: 6.3 | F8: 5.61 | G8: 6.62
A9: μ5 | B9: － | C9: － | D9: － | E9: 7.22 | F9: 6.06 | G9: 8.47
A10: σ | B10: 0.89 | C10: 1.03 | D10: 0.84 | E10: 1.27 | F10: 1.51 | G10: 2.66
A11: 標本数N | B11: 42 | C11: 20 | D11: 14 | E11: 125 | F11: 39 | G11: 55
A12: lnL1 | B12: -36.53 | C12: -19.77 | D12: -10.99 | E12: -164.76 | F12: -56.78 | G12: -77.2
A13: lnL0 | B13: -58.22 | C13: -27.73 | D13: -19.41 | E13: -223.97 | F13: -69.88 | G13: -98.55
A14: χ² | B14: 43.39 | C14: 15.9 | D14: 16.84 | E14: 118.42 | F14: 26.2 | G14: 42.69
A15: ρ² | B15: 0.37 | C15: 0.29 | D15: 0.43 | E15: 0.26 | F15: 0.19 | G15: 0.22
A18: 被害モードの定義と損失率（被害区分は最大値を使用）
A19: 被害モード | B19: 製造業 被害区分 | C19: 製造業 損失率(最大値) | D19: 非製造業 被害区分 | E19: 非製造業 損失率(最大値)
A20: 0 | B20: =0% -> 0 | C20: 0 | D20: =0% -> 0 | E20: 0
A21: 1 | B21: 0% < 復旧費用率 ≤ 25% | C21: 0.25 | D21: 0% < 復旧費用率 ≤ 25% | E21: 0.25
A22: 2 | B22: 25% < 復旧費用率 ≤ 50% | C22: 0.5 | D22: 25% < 復旧費用率 ≤ 50% | E22: 0.5
A23: 3 | B23: 50% < 復旧費用率 ≤ 100% | C23: 1 | D23: 50% < 復旧費用率 ≤ 75% | E23: 0.75
A24: 4 | B24: － | C24: － | D24: 75% < 復旧費用率 < 100% | E24: 0.9
A25: 5 | B25: － | C25: － | D25: =100% -> 1 | E25: 1
A27: ※ 非製造業の被害モード4（75%超〜100%未満）は、被害モード5（=100%）が別にあるため、上限の100%ではなく90%を損失率とした。
A28: ※ 製造業は標本数の制約から、被害モード3〜5を被害モード3（50%超〜100%）に統合している（論文 表3-5）。
A29: ※ 浸水深0cmでは ln(0) が定義できないため、損失率は0とする。

Sheet 1_製造業
A1: 製造業：フラジリティ曲線と損失率曲線
A3: 被害モード | B3: 0 | C3: 1 | D3: 2 | E3: 3
A4: 損失率 | B4: =データ!$C$20 -> 0 | C4: =データ!$C$21 -> 0.25 | D4: =データ!$C$22 -> 0.5 | E4: =データ!$C$23 -> 1
A5: μ | C5: =データ!$B$5 -> 3.16 | D5: =データ!$B$6 -> 5.09 | E5: =データ!$B$7 -> 6.04
A6: σ | B6: =データ!$B$10 -> 0.89
A9: 浸水深(cm) | B9: 被害モード1以上率 | C9: 被害モード2以上率 | D9: 被害モード3以上率 | E9: 被害モード0率(無被害) | F9: 被害モード1率 | G9: 被害モード2率 | H9: 被害モード3率 | I9: 損失率
A10: 0 | B10: =IF($A10<=0,0,_xlfn.NORM.S.DIST((LN($A10)-C$5)/$B$6,TRUE())) -> 0 | C10: =IF($A10<=0,0,_xlfn.NORM.S.DIST((LN($A10)-D$5)/$B$6,TRUE())) -> 0 | D10: =IF($A10<=0,0,_xlfn.NORM.S.DIST((LN($A10)-E$5)/$B$6,TRUE())) -> 0 | E10: =1-B10 -> 1 | F10: =B10-C10 -> 0 | G10: =C10-D10 -> 0 | H10: =D10 -> 0 | I10: =E10*$B$4+F10*$C$4+G10*$D$4+H10*$E$4 -> 0
A11: 10 | B11: =IF($A11<=0,0,_xlfn.NORM.S.DIST((LN($A11)-C$5)/$B$6,TRUE())) -> 0.16767654 | C11: =IF($A11<=0,0,_xlfn.NORM.S.DIST((LN($A11)-D$5)/$B$6,TRUE())) -> 0.00086831566 | D11: =IF($A11<=0,0,_xlfn.NORM.S.DIST((LN($A11)-E$5)/$B$6,TRUE())) -> 1.3384552e-05 | E11: =1-B11 -> 0.83232346 | F11: =B11-C11 -> 0.16680822 | G11: =C11-D11 -> 0.0008549311 | H11: =D11 -> 1.3384552e-05 | I11: =E11*$B$4+F11*$C$4+G11*$D$4+H11*$E$4 -> 0.042142906
A12: 20 | B12: =IF($A12<=0,0,_xlfn.NORM.S.DIST((LN($A12)-C$5)/$B$6,TRUE())) -> 0.42678297 | C12: =IF($A12<=0,0,_xlfn.NORM.S.DIST((LN($A12)-D$5)/$B$6,TRUE())) -> 0.0093085678 | D12: =IF($A12<=0,0,_xlfn.NORM.S.DIST((LN($A12)-E$5)/$B$6,TRUE())) -> 0.00031250134 | E12: =1-B12 -> 0.57321703 | F12: =B12-C12 -> 0.4174744 | G12: =C12-D12 -> 0.0089960664 | H12: =D12 -> 0.00031250134 | I12: =E12*$B$4+F12*$C$4+G12*$D$4+H12*$E$4 -> 0.10917914
A13: 30 | B13: =IF($A13<=0,0,_xlfn.NORM.S.DIST((LN($A13)-C$5)/$B$6,TRUE())) -> 0.60680767 | C13: =IF($A13<=0,0,_xlfn.NORM.S.DIST((LN($A13)-D$5)/$B$6,TRUE())) -> 0.028878944 | D13: =IF($A13<=0,0,_xlfn.NORM.S.DIST((LN($A13)-E$5)/$B$6,TRUE())) -> 0.0015136766 | E13: =1-B13 -> 0.39319233 | F13: =B13-C13 -> 0.57792873 | G13: =C13-D13 -> 0.027365267 | H13: =D13 -> 0.0015136766 | I13: =E13*$B$4+F13*$C$4+G13*$D$4+H13*$E$4 -> 0.15967849
A14: 40 | B14: =IF($A14<=0,0,_xlfn.NORM.S.DIST((LN($A14)-C$5)/$B$6,TRUE())) -> 0.7238264 | C14: =IF($A14<=0,0,_xlfn.NORM.S.DIST((LN($A14)-D$5)/$B$6,TRUE())) -> 0.057709893 | D14: =IF($A14<=0,0,_xlfn.NORM.S.DIST((LN($A14)-E$5)/$B$6,TRUE())) -> 0.0041244511 | E14: =1-B14 -> 0.2761736 | F14: =B14-C14 -> 0.66611651 | G14: =C14-D14 -> 0.053585442 | H14: =D14 -> 0.0041244511 | I14: =E14*$B$4+F14*$C$4+G14*$D$4+H14*$E$4 -> 0.1974463
A15: 50 | B15: =IF($A15<=0,0,_xlfn.NORM.S.DIST((LN($A15)-C$5)/$B$6,TRUE())) -> 0.80093611 | C15: =IF($A15<=0,0,_xlfn.NORM.S.DIST((LN($A15)-D$5)/$B$6,TRUE())) -> 0.092823004 | D15: =IF($A15<=0,0,_xlfn.NORM.S.DIST((LN($A15)-E$5)/$B$6,TRUE())) -> 0.0084016108 | E15: =1-B15 -> 0.19906389 | F15: =B15-C15 -> 0.70811311 | G15: =C15-D15 -> 0.084421393 | H15: =D15 -> 0.0084016108 | I15: =E15*$B$4+F15*$C$4+G15*$D$4+H15*$E$4 -> 0.22764058
A16: 60 | B16: =IF($A16<=0,0,_xlfn.NORM.S.DIST((LN($A16)-C$5)/$B$6,TRUE())) -> 0.85310079 | C16: =IF($A16<=0,0,_xlfn.NORM.S.DIST((LN($A16)-D$5)/$B$6,TRUE())) -> 0.13163109 | D16: =IF($A16<=0,0,_xlfn.NORM.S.DIST((LN($A16)-E$5)/$B$6,TRUE())) -> 0.014403059 | E16: =1-B16 -> 0.14689921 | F16: =B16-C16 -> 0.7214697 | G16: =C16-D16 -> 0.11722803 | H16: =D16 -> 0.014403059 | I16: =E16*$B$4+F16*$C$4+G16*$D$4+H16*$E$4 -> 0.2533845
A17: 70 | B17: =IF($A17<=0,0,_xlfn.NORM.S.DIST((LN($A17)-C$5)/$B$6,TRUE())) -> 0.88934051 | C17: =IF($A17<=0,0,_xlfn.NORM.S.DIST((LN($A17)-D$5)/$B$6,TRUE())) -> 0.17219904 | D17: =IF($A17<=0,0,_xlfn.NORM.S.DIST((LN($A17)-E$5)/$B$6,TRUE())) -> 0.022061171 | E17: =1-B17 -> 0.11065949 | F17: =B17-C17 -> 0.71714147 | G17: =C17-D17 -> 0.15013787 | H17: =D17 -> 0.022061171 | I17: =E17*$B$4+F17*$C$4+G17*$D$4+H17*$E$4 -> 0.27641547
A18: 80 | B18: =IF($A18<=0,0,_xlfn.NORM.S.DIST((LN($A18)-C$5)/$B$6,TRUE())) -> 0.91513372 | C18: =IF($A18<=0,0,_xlfn.NORM.S.DIST((LN($A18)-D$5)/$B$6,TRUE())) -> 0.21316842 | D18: =IF($A18<=0,0,_xlfn.NORM.S.DIST((LN($A18)-E$5)/$B$6,TRUE())) -> 0.031238772 | E18: =1-B18 -> 0.084866283 | F18: =B18-C18 -> 0.70196529 | G18: =C18-D18 -> 0.18192965 | H18: =D18 -> 0.031238772 | I18: =E18*$B$4+F18*$C$4+G18*$D$4+H18*$E$4 -> 0.29769492
A19: 90 | B19: =IF($A19<=0,0,_xlfn.NORM.S.DIST((LN($A19)-C$5)/$B$6,TRUE())) -> 0.9338899 | C19: =IF($A19<=0,0,_xlfn.NORM.S.DIST((LN($A19)-D$5)/$B$6,TRUE())) -> 0.25362198 | D19: =IF($A19<=0,0,_xlfn.NORM.S.DIST((LN($A19)-E$5)/$B$6,TRUE())) -> 0.041765945 | E19: =1-B19 -> 0.066110105 | F19: =B19-C19 -> 0.68026791 | G19: =C19-D19 -> 0.21185604 | H19: =D19 -> 0.041765945 | I19: =E19*$B$4+F19*$C$4+G19*$D$4+H19*$E$4 -> 0.31776094
A20: 100 | B20: =IF($A20<=0,0,_xlfn.NORM.S.DIST((LN($A20)-C$5)/$B$6,TRUE())) -> 0.94778933 | C20: =IF($A20<=0,0,_xlfn.NORM.S.DIST((LN($A20)-D$5)/$B$6,TRUE())) -> 0.29296184 | D20: =IF($A20<=0,0,_xlfn.NORM.S.DIST((LN($A20)-E$5)/$B$6,TRUE())) -> 0.053462657 | E20: =1-B20 -> 0.052210667 | F20: =B20-C20 -> 0.65482749 | G20: =C20-D20 -> 0.23949918 | H20: =D20 -> 0.053462657 | I20: =E20*$B$4+F20*$C$4+G20*$D$4+H20*$E$4 -> 0.33691912
A21: 110 | B21: =IF($A21<=0,0,_xlfn.NORM.S.DIST((LN($A21)-C$5)/$B$6,TRUE())) -> 0.95826313 | C21: =IF($A21<=0,0,_xlfn.NORM.S.DIST((LN($A21)-D$5)/$B$6,TRUE())) -> 0.33081547 | D21: =IF($A21<=0,0,_xlfn.NORM.S.DIST((LN($A21)-E$5)/$B$6,TRUE())) -> 0.066151981 | E21: =1-B21 -> 0.041736869 | F21: =B21-C21 -> 0.62744766 | G21: =C21-D21 -> 0.26466349 | H21: =D21 -> 0.066151981 | I21: =E21*$B$4+F21*$C$4+G21*$D$4+H21*$E$4 -> 0.35534564
... A70: 600 | B70: =IF($A70<=0,0,_xlfn.NORM.S.DIST((LN($A70)-C$5)/$B$6,TRUE())) -> 0.99986208 | C70: =IF($A70<=0,0,_xlfn.NORM.S.DIST((LN($A70)-D$5)/$B$6,TRUE())) -> 0.92901038 | D70: =IF($A70<=0,0,_xlfn.NORM.S.DIST((LN($A70)-E$5)/$B$6,TRUE())) -> 0.65580634 | E70: =1-B70 -> 0.00013791617 | F70: =B70-C70 -> 0.070851702 | G70: =C70-D70 -> 0.27320404 | H70: =D70 -> 0.65580634 | I70: =E70*$B$4+F70*$C$4+G70*$D$4+H70*$E$4 -> 0.81012129

Sheet 2_生活関連型産業
A1: 生活関連型産業：フラジリティ曲線と損失率曲線
A3: 被害モード | B3: 0 | C3: 1 | D3: 2 | E3: 3
A4: 損失率 | B4: =データ!$C$20 -> 0 | C4: =データ!$C$21 -> 0.25 | D4: =データ!$C$22 -> 0.5 | E4: =データ!$C$23 -> 1
A5: μ | C5: =データ!$C$5 -> 3.49 | D5: =データ!$C$6 -> 5 | E5: =データ!$C$7 -> 6.32
A6: σ | B6: =データ!$C$10 -> 1.03
A9: 浸水深(cm) | B9: 被害モード1以上率 | C9: 被害モード2以上率 | D9: 被害モード3以上率 | E9: 被害モード0率(無被害) | F9: 被害モード1率 | G9: 被害モード2率 | H9: 被害モード3率 | I9: 損失率
A10: 0 | B10: =IF($A10<=0,0,_xlfn.NORM.S.DIST((LN($A10)-C$5)/$B$6,TRUE())) -> 0 | C10: =IF($A10<=0,0,_xlfn.NORM.S.DIST((LN($A10)-D$5)/$B$6,TRUE())) -> 0 | D10: =IF($A10<=0,0,_xlfn.NORM.S.DIST((LN($A10)-E$5)/$B$6,TRUE())) -> 0 | E10: =1-B10 -> 1 | F10: =B10-C10 -> 0 | G10: =C10-D10 -> 0 | H10: =D10 -> 0 | I10: =E10*$B$4+F10*$C$4+G10*$D$4+H10*$E$4 -> 0
A11: 10 | B11: =IF($A11<=0,0,_xlfn.NORM.S.DIST((LN($A11)-C$5)/$B$6,TRUE())) -> 0.12449008 | C11: =IF($A11<=0,0,_xlfn.NORM.S.DIST((LN($A11)-D$5)/$B$6,TRUE())) -> 0.0044113441 | D11: =IF($A11<=0,0,_xlfn.NORM.S.DIST((LN($A11)-E$5)/$B$6,TRUE())) -> 4.8016384e-05 | E11: =1-B11 -> 0.87550992 | F11: =B11-C11 -> 0.12007874 | G11: =C11-D11 -> 0.0043633277 | H11: =D11 -> 4.8016384e-05 | I11: =E11*$B$4+F11*$C$4+G11*$D$4+H11*$E$4 -> 0.032249365
A12: 20 | B12: =IF($A12<=0,0,_xlfn.NORM.S.DIST((LN($A12)-C$5)/$B$6,TRUE())) -> 0.31565936 | C12: =IF($A12<=0,0,_xlfn.NORM.S.DIST((LN($A12)-D$5)/$B$6,TRUE())) -> 0.025833917 | D12: =IF($A12<=0,0,_xlfn.NORM.S.DIST((LN($A12)-E$5)/$B$6,TRUE())) -> 0.00062450657 | E12: =1-B12 -> 0.68434064 | F12: =B12-C12 -> 0.28982544 | G12: =C12-D12 -> 0.025209411 | H12: =D12 -> 0.00062450657 | I12: =E12*$B$4+F12*$C$4+G12*$D$4+H12*$E$4 -> 0.085685572
A13: 30 | B13: =IF($A13<=0,0,_xlfn.NORM.S.DIST((LN($A13)-C$5)/$B$6,TRUE())) -> 0.4656473 | C13: =IF($A13<=0,0,_xlfn.NORM.S.DIST((LN($A13)-D$5)/$B$6,TRUE())) -> 0.060302936 | D13: =IF($A13<=0,0,_xlfn.NORM.S.DIST((LN($A13)-E$5)/$B$6,TRUE())) -> 0.002299985 | E13: =1-B13 -> 0.5343527 | F13: =B13-C13 -> 0.40534437 | G13: =C13-D13 -> 0.058002951 | H13: =D13 -> 0.002299985 | I13: =E13*$B$4+F13*$C$4+G13*$D$4+H13*$E$4 -> 0.13263755
A14: 40 | B14: =IF($A14<=0,0,_xlfn.NORM.S.DIST((LN($A14)-C$5)/$B$6,TRUE())) -> 0.57655452 | C14: =IF($A14<=0,0,_xlfn.NORM.S.DIST((LN($A14)-D$5)/$B$6,TRUE())) -> 0.10152099 | D14: =IF($A14<=0,0,_xlfn.NORM.S.DIST((LN($A14)-E$5)/$B$6,TRUE())) -> 0.0053172358 | E14: =1-B14 -> 0.42344548 | F14: =B14-C14 -> 0.47503354 | G14: =C14-D14 -> 0.09620375 | H14: =D14 -> 0.0053172358 | I14: =E14*$B$4+F14*$C$4+G14*$D$4+H14*$E$4 -> 0.1721775
A15: 50 | B15: =IF($A15<=0,0,_xlfn.NORM.S.DIST((LN($A15)-C$5)/$B$6,TRUE())) -> 0.65899838 | C15: =IF($A15<=0,0,_xlfn.NORM.S.DIST((LN($A15)-D$5)/$B$6,TRUE())) -> 0.14541825 | D15: =IF($A15<=0,0,_xlfn.NORM.S.DIST((LN($A15)-E$5)/$B$6,TRUE())) -> 0.0096977297 | E15: =1-B15 -> 0.34100162 | F15: =B15-C15 -> 0.51358013 | G15: =C15-D15 -> 0.13572052 | H15: =D15 -> 0.0096977297 | I15: =E15*$B$4+F15*$C$4+G15*$D$4+H15*$E$4 -> 0.20595302
A16: 60 | B16: =IF($A16<=0,0,_xlfn.NORM.S.DIST((LN($A16)-C$5)/$B$6,TRUE())) -> 0.7213116 | C16: =IF($A16<=0,0,_xlfn.NORM.S.DIST((LN($A16)-D$5)/$B$6,TRUE())) -> 0.18962552 | D16: =IF($A16<=0,0,_xlfn.NORM.S.DIST((LN($A16)-E$5)/$B$6,TRUE())) -> 0.015354217 | E16: =1-B16 -> 0.2786884 | F16: =B16-C16 -> 0.53168608 | G16: =C16-D16 -> 0.1742713 | H16: =D16 -> 0.015354217 | I16: =E16*$B$4+F16*$C$4+G16*$D$4+H16*$E$4 -> 0.23541139
A17: 70 | B17: =IF($A17<=0,0,_xlfn.NORM.S.DIST((LN($A17)-C$5)/$B$6,TRUE())) -> 0.76925731 | C17: =IF($A17<=0,0,_xlfn.NORM.S.DIST((LN($A17)-D$5)/$B$6,TRUE())) -> 0.23281239 | D17: =IF($A17<=0,0,_xlfn.NORM.S.DIST((LN($A17)-E$5)/$B$6,TRUE())) -> 0.022153769 | E17: =1-B17 -> 0.23074269 | F17: =B17-C17 -> 0.53644492 | G17: =C17-D17 -> 0.21065862 | H17: =D17 -> 0.022153769 | I17: =E17*$B$4+F17*$C$4+G17*$D$4+H17*$E$4 -> 0.26159431
A18: 80 | B18: =IF($A18<=0,0,_xlfn.NORM.S.DIST((LN($A18)-C$5)/$B$6,TRUE())) -> 0.80676733 | C18: =IF($A18<=0,0,_xlfn.NORM.S.DIST((LN($A18)-D$5)/$B$6,TRUE())) -> 0.27426173 | D18: =IF($A18<=0,0,_xlfn.NORM.S.DIST((LN($A18)-E$5)/$B$6,TRUE())) -> 0.029950096 | E18: =1-B18 -> 0.19323267 | F18: =B18-C18 -> 0.5325056 | G18: =C18-D18 -> 0.24431164 | H18: =D18 -> 0.029950096 | I18: =E18*$B$4+F18*$C$4+G18*$D$4+H18*$E$4 -> 0.28523232
A19: 90 | B19: =IF($A19<=0,0,_xlfn.NORM.S.DIST((LN($A19)-C$5)/$B$6,TRUE())) -> 0.83655509 | C19: =IF($A19<=0,0,_xlfn.NORM.S.DIST((LN($A19)-D$5)/$B$6,TRUE())) -> 0.31361771 | D19: =IF($A19<=0,0,_xlfn.NORM.S.DIST((LN($A19)-E$5)/$B$6,TRUE())) -> 0.038599456 | E19: =1-B19 -> 0.16344491 | F19: =B19-C19 -> 0.52293738 | G19: =C19-D19 -> 0.27501826 | H19: =D19 -> 0.038599456 | I19: =E19*$B$4+F19*$C$4+G19*$D$4+H19*$E$4 -> 0.30684293
A20: 100 | B20: =IF($A20<=0,0,_xlfn.NORM.S.DIST((LN($A20)-C$5)/$B$6,TRUE())) -> 0.86052687 | C20: =IF($A20<=0,0,_xlfn.NORM.S.DIST((LN($A20)-D$5)/$B$6,TRUE())) -> 0.35073758 | D20: =IF($A20<=0,0,_xlfn.NORM.S.DIST((LN($A20)-E$5)/$B$6,TRUE())) -> 0.047968019 | E20: =1-B20 -> 0.13947313 | F20: =B20-C20 -> 0.50978929 | G20: =C20-D20 -> 0.30276956 | H20: =D20 -> 0.047968019 | I20: =E20*$B$4+F20*$C$4+G20*$D$4+H20*$E$4 -> 0.32680012
A21: 110 | B21: =IF($A21<=0,0,_xlfn.NORM.S.DIST((LN($A21)-C$5)/$B$6,TRUE())) -> 0.88004738 | C21: =IF($A21<=0,0,_xlfn.NORM.S.DIST((LN($A21)-D$5)/$B$6,TRUE())) -> 0.38560376 | D21: =IF($A21<=0,0,_xlfn.NORM.S.DIST((LN($A21)-E$5)/$B$6,TRUE())) -> 0.057934799 | E21: =1-B21 -> 0.11995262 | F21: =B21-C21 -> 0.49444361 | G21: =C21-D21 -> 0.32766896 | H21: =D21 -> 0.057934799 | I21: =E21*$B$4+F21*$C$4+G21*$D$4+H21*$E$4 -> 0.34538018
... A70: 600 | B70: =IF($A70<=0,0,_xlfn.NORM.S.DIST((LN($A70)-C$5)/$B$6,TRUE())) -> 0.99761569 | C70: =IF($A70<=0,0,_xlfn.NORM.S.DIST((LN($A70)-D$5)/$B$6,TRUE())) -> 0.91248897 | D70: =IF($A70<=0,0,_xlfn.NORM.S.DIST((LN($A70)-E$5)/$B$6,TRUE())) -> 0.52976891 | E70: =1-B70 -> 0.0023843116 | F70: =B70-C70 -> 0.085126719 | G70: =C70-D70 -> 0.38272006 | H70: =D70 -> 0.52976891 | I70: =E70*$B$4+F70*$C$4+G70*$D$4+H70*$E$4 -> 0.74241062

Sheet 3_基礎素材型産業
A1: 基礎素材型産業：フラジリティ曲線と損失率曲線
A3: 被害モード | B3: 0 | C3: 1 | D3: 2 | E3: 3
A4: 損失率 | B4: =データ!$C$20 -> 0 | C4: =データ!$C$21 -> 0.25 | D4: =データ!$C$22 -> 0.5 | E4: =データ!$C$23 -> 1
A5: μ | C5: =データ!$D$5 -> 2.72 | D5: =データ!$D$6 -> 4.99 | E5: =データ!$D$7 -> 5.59
A6: σ | B6: =データ!$D$10 -> 0.84
A9: 浸水深(cm) | B9: 被害モード1以上率 | C9: 被害モード2以上率 | D9: 被害モード3以上率 | E9: 被害モード0率(無被害) | F9: 被害モード1率 | G9: 被害モード2率 | H9: 被害モード3率 | I9: 損失率
A10: 0 | B10: =IF($A10<=0,0,_xlfn.NORM.S.DIST((LN($A10)-C$5)/$B$6,TRUE())) -> 0 | C10: =IF($A10<=0,0,_xlfn.NORM.S.DIST((LN($A10)-D$5)/$B$6,TRUE())) -> 0 | D10: =IF($A10<=0,0,_xlfn.NORM.S.DIST((LN($A10)-E$5)/$B$6,TRUE())) -> 0 | E10: =1-B10 -> 1 | F10: =B10-C10 -> 0 | G10: =C10-D10 -> 0 | H10: =D10 -> 0 | I10: =E10*$B$4+F10*$C$4+G10*$D$4+H10*$E$4 -> 0
A11: 10 | B11: =IF($A11<=0,0,_xlfn.NORM.S.DIST((LN($A11)-C$5)/$B$6,TRUE())) -> 0.30962185 | C11: =IF($A11<=0,0,_xlfn.NORM.S.DIST((LN($A11)-D$5)/$B$6,TRUE())) -> 0.0006888004 | D11: =IF($A11<=0,0,_xlfn.NORM.S.DIST((LN($A11)-E$5)/$B$6,TRUE())) -> 4.5467148e-05 | E11: =1-B11 -> 0.69037815 | F11: =B11-C11 -> 0.30893305 | G11: =C11-D11 -> 0.00064333325 | H11: =D11 -> 4.5467148e-05 | I11: =E11*$B$4+F11*$C$4+G11*$D$4+H11*$E$4 -> 0.077600396
A12: 20 | B12: =IF($A12<=0,0,_xlfn.NORM.S.DIST((LN($A12)-C$5)/$B$6,TRUE())) -> 0.6286397 | C12: =IF($A12<=0,0,_xlfn.NORM.S.DIST((LN($A12)-D$5)/$B$6,TRUE())) -> 0.0087952198 | D12: =IF($A12<=0,0,_xlfn.NORM.S.DIST((LN($A12)-E$5)/$B$6,TRUE())) -> 0.0010061398 | E12: =1-B12 -> 0.3713603 | F12: =B12-C12 -> 0.61984448 | G12: =C12-D12 -> 0.0077890801 | H12: =D12 -> 0.0010061398 | I12: =E12*$B$4+F12*$C$4+G12*$D$4+H12*$E$4 -> 0.1598618
A13: 30 | B13: =IF($A13<=0,0,_xlfn.NORM.S.DIST((LN($A13)-C$5)/$B$6,TRUE())) -> 0.7913026 | C13: =IF($A13<=0,0,_xlfn.NORM.S.DIST((LN($A13)-D$5)/$B$6,TRUE())) -> 0.029283371 | D13: =IF($A13<=0,0,_xlfn.NORM.S.DIST((LN($A13)-E$5)/$B$6,TRUE())) -> 0.0045841035 | E13: =1-B13 -> 0.2086974 | F13: =B13-C13 -> 0.76201923 | G13: =C13-D13 -> 0.024699267 | H13: =D13 -> 0.0045841035 | I13: =E13*$B$4+F13*$C$4+G13*$D$4+H13*$E$4 -> 0.20743854
A14: 40 | B14: =IF($A14<=0,0,_xlfn.NORM.S.DIST((LN($A14)-C$5)/$B$6,TRUE())) -> 0.87563261 | C14: =IF($A14<=0,0,_xlfn.NORM.S.DIST((LN($A14)-D$5)/$B$6,TRUE())) -> 0.060696506 | D14: =IF($A14<=0,0,_xlfn.NORM.S.DIST((LN($A14)-E$5)/$B$6,TRUE())) -> 0.011810488 | E14: =1-B14 -> 0.12436739 | F14: =B14-C14 -> 0.8149361 | G14: =C14-D14 -> 0.048886018 | H14: =D14 -> 0.011810488 | I14: =E14*$B$4+F14*$C$4+G14*$D$4+H14*$E$4 -> 0.23998752
A15: 50 | B15: =IF($A15<=0,0,_xlfn.NORM.S.DIST((LN($A15)-C$5)/$B$6,TRUE())) -> 0.92206143 | C15: =IF($A15<=0,0,_xlfn.NORM.S.DIST((LN($A15)-D$5)/$B$6,TRUE())) -> 0.099692455 | D15: =IF($A15<=0,0,_xlfn.NORM.S.DIST((LN($A15)-E$5)/$B$6,TRUE())) -> 0.022880474 | E15: =1-B15 -> 0.077938575 | F15: =B15-C15 -> 0.82236897 | G15: =C15-D15 -> 0.076811981 | H15: =D15 -> 0.022880474 | I15: =E15*$B$4+F15*$C$4+G15*$D$4+H15*$E$4 -> 0.26687871
A16: 60 | B16: =IF($A16<=0,0,_xlfn.NORM.S.DIST((LN($A16)-C$5)/$B$6,TRUE())) -> 0.94909323 | C16: =IF($A16<=0,0,_xlfn.NORM.S.DIST((LN($A16)-D$5)/$B$6,TRUE())) -> 0.14315386 | D16: =IF($A16<=0,0,_xlfn.NORM.S.DIST((LN($A16)-E$5)/$B$6,TRUE())) -> 0.037493636 | E16: =1-B16 -> 0.050906769 | F16: =B16-C16 -> 0.80593937 | G16: =C16-D16 -> 0.10566022 | H16: =D16 -> 0.037493636 | I16: =E16*$B$4+F16*$C$4+G16*$D$4+H16*$E$4 -> 0.29180859
A17: 70 | B17: =IF($A17<=0,0,_xlfn.NORM.S.DIST((LN($A17)-C$5)/$B$6,TRUE())) -> 0.96559286 | C17: =IF($A17<=0,0,_xlfn.NORM.S.DIST((LN($A17)-D$5)/$B$6,TRUE())) -> 0.18868737 | D17: =IF($A17<=0,0,_xlfn.NORM.S.DIST((LN($A17)-E$5)/$B$6,TRUE())) -> 0.055129569 | E17: =1-B17 -> 0.034407137 | F17: =B17-C17 -> 0.7769055 | G17: =C17-D17 -> 0.1335578 | H17: =D17 -> 0.055129569 | I17: =E17*$B$4+F17*$C$4+G17*$D$4+H17*$E$4 -> 0.31613484
A18: 80 | B18: =IF($A18<=0,0,_xlfn.NORM.S.DIST((LN($A18)-C$5)/$B$6,TRUE())) -> 0.97606965 | C18: =IF($A18<=0,0,_xlfn.NORM.S.DIST((LN($A18)-D$5)/$B$6,TRUE())) -> 0.23460108 | D18: =IF($A18<=0,0,_xlfn.NORM.S.DIST((LN($A18)-E$5)/$B$6,TRUE())) -> 0.075208015 | E18: =1-B18 -> 0.023930353 | F18: =B18-C18 -> 0.74146857 | G18: =C18-D18 -> 0.15939306 | H18: =D18 -> 0.075208015 | I18: =E18*$B$4+F18*$C$4+G18*$D$4+H18*$E$4 -> 0.34027169
A19: 90 | B19: =IF($A19<=0,0,_xlfn.NORM.S.DIST((LN($A19)-C$5)/$B$6,TRUE())) -> 0.9829472 | C19: =IF($A19<=0,0,_xlfn.NORM.S.DIST((LN($A19)-D$5)/$B$6,TRUE())) -> 0.27975822 | D19: =IF($A19<=0,0,_xlfn.NORM.S.DIST((LN($A19)-E$5)/$B$6,TRUE())) -> 0.097170193 | E19: =1-B19 -> 0.017052797 | F19: =B19-C19 -> 0.70318899 | G19: =C19-D19 -> 0.18258802 | H19: =D19 -> 0.097170193 | I19: =E19*$B$4+F19*$C$4+G19*$D$4+H19*$E$4 -> 0.36426145
A20: 100 | B20: =IF($A20<=0,0,_xlfn.NORM.S.DIST((LN($A20)-C$5)/$B$6,TRUE())) -> 0.98759185 | C20: =IF($A20<=0,0,_xlfn.NORM.S.DIST((LN($A20)-D$5)/$B$6,TRUE())) -> 0.32342926 | D20: =IF($A20<=0,0,_xlfn.NORM.S.DIST((LN($A20)-E$5)/$B$6,TRUE())) -> 0.12051495 | E20: =1-B20 -> 0.012408153 | F20: =B20-C20 -> 0.66416259 | G20: =C20-D20 -> 0.20291431 | H20: =D20 -> 0.12051495 | I20: =E20*$B$4+F20*$C$4+G20*$D$4+H20*$E$4 -> 0.38801275
A21: 110 | B21: =IF($A21<=0,0,_xlfn.NORM.S.DIST((LN($A21)-C$5)/$B$6,TRUE())) -> 0.99080609 | C21: =IF($A21<=0,0,_xlfn.NORM.S.DIST((LN($A21)-D$5)/$B$6,TRUE())) -> 0.36517265 | D21: =IF($A21<=0,0,_xlfn.NORM.S.DIST((LN($A21)-E$5)/$B$6,TRUE())) -> 0.14481083 | E21: =1-B21 -> 0.0091939089 | F21: =B21-C21 -> 0.62563344 | G21: =C21-D21 -> 0.22036182 | H21: =D21 -> 0.14481083 | I21: =E21*$B$4+F21*$C$4+G21*$D$4+H21*$E$4 -> 0.4114001
... A70: 600 | B70: =IF($A70<=0,0,_xlfn.NORM.S.DIST((LN($A70)-C$5)/$B$6,TRUE())) -> 0.99999399 | C70: =IF($A70<=0,0,_xlfn.NORM.S.DIST((LN($A70)-D$5)/$B$6,TRUE())) -> 0.95302467 | D70: =IF($A70<=0,0,_xlfn.NORM.S.DIST((LN($A70)-E$5)/$B$6,TRUE())) -> 0.83163102 | E70: =1-B70 -> 6.0080036e-06 | F70: =B70-C70 -> 0.046969324 | G70: =C70-D70 -> 0.12139365 | H70: =D70 -> 0.83163102 | I70: =E70*$B$4+F70*$C$4+G70*$D$4+H70*$E$4 -> 0.90407017

Sheet 4_非製造業
A1: 非製造業：フラジリティ曲線と損失率曲線
A3: 被害モード | B3: 0 | C3: 1 | D3: 2 | E3: 3 | F3: 4 | G3: 5
A4: 損失率 | B4: =データ!$E$20 -> 0 | C4: =データ!$E$21 -> 0.25 | D4: =データ!$E$22 -> 0.5 | E4: =データ!$E$23 -> 0.75 | F4: =データ!$E$24 -> 0.9 | G4: =データ!$E$25 -> 1
A5: μ | C5: =データ!$E$5 -> 2.27 | D5: =データ!$E$6 -> 4.76 | E5: =データ!$E$7 -> 5.73 | F5: =データ!$E$8 -> 6.3 | G5: =データ!$E$9 -> 7.22
A6: σ | B6: =データ!$E$10 -> 1.27
A9: 浸水深(cm) | B9: 被害モード1以上率 | C9: 被害モード2以上率 | D9: 被害モード3以上率 | E9: 被害モード4以上率 | F9: 被害モード5以上率 | G9: 被害モード0率(無被害) | H9: 被害モード1率 | I9: 被害モード2率 | J9: 被害モード3率 | K9: 被害モード4率 | L9: 被害モード5率 | M9: 損失率
A10: 0 | B10: =IF($A10<=0,0,_xlfn.NORM.S.DIST((LN($A10)-C$5)/$B$6,TRUE())) -> 0 | C10: =IF($A10<=0,0,_xlfn.NORM.S.DIST((LN($A10)-D$5)/$B$6,TRUE())) -> 0 | D10: =IF($A10<=0,0,_xlfn.NORM.S.DIST((LN($A10)-E$5)/$B$6,TRUE())) -> 0 | E10: =IF($A10<=0,0,_xlfn.NORM.S.DIST((LN($A10)-F$5)/$B$6,TRUE())) -> 0 | F10: =IF($A10<=0,0,_xlfn.NORM.S.DIST((LN($A10)-G$5)/$B$6,TRUE())) -> 0 | G10: =1-B10 -> 1 | H10: =B10-C10 -> 0 | I10: =C10-D10 -> 0 | J10: =D10-E10 -> 0 | K10: =E10-F10 -> 0 | L10: =F10 -> 0 | M10: =G10*$B$4+H10*$C$4+I10*$D$4+J10*$E$4+K10*$F$4+L10*$G$4 -> 0
A11: 10 | B11: =IF($A11<=0,0,_xlfn.NORM.S.DIST((LN($A11)-C$5)/$B$6,TRUE())) -> 0.51023476 | C11: =IF($A11<=0,0,_xlfn.NORM.S.DIST((LN($A11)-D$5)/$B$6,TRUE())) -> 0.026496843 | D11: =IF($A11<=0,0,_xlfn.NORM.S.DIST((LN($A11)-E$5)/$B$6,TRUE())) -> 0.0034800022 | E11: =IF($A11<=0,0,_xlfn.NORM.S.DIST((LN($A11)-F$5)/$B$6,TRUE())) -> 0.00082316618 | F11: =IF($A11<=0,0,_xlfn.NORM.S.DIST((LN($A11)-G$5)/$B$6,TRUE())) -> 5.3977353e-05 | G11: =1-B11 -> 0.48976524 | H11: =B11-C11 -> 0.48373792 | I11: =C11-D11 -> 0.023016841 | J11: =D11-E11 -> 0.002656836 | K11: =E11-F11 -> 0.00076918882 | L11: =F11 -> 5.3977353e-05 | M11: =G11*$B$4+H11*$C$4+I11*$D$4+J11*$E$4+K11*$F$4+L11*$G$4 -> 0.13518177
A12: 20 | B12: =IF($A12<=0,0,_xlfn.NORM.S.DIST((LN($A12)-C$5)/$B$6,TRUE())) -> 0.71615022 | C12: =IF($A12<=0,0,_xlfn.NORM.S.DIST((LN($A12)-D$5)/$B$6,TRUE())) -> 0.082387919 | D12: =IF($A12<=0,0,_xlfn.NORM.S.DIST((LN($A12)-E$5)/$B$6,TRUE())) -> 0.015660647 | E12: =IF($A12<=0,0,_xlfn.NORM.S.DIST((LN($A12)-F$5)/$B$6,TRUE())) -> 0.0046369903 | F12: =IF($A12<=0,0,_xlfn.NORM.S.DIST((LN($A12)-G$5)/$B$6,TRUE())) -> 0.00044020147 | G12: =1-B12 -> 0.28384978 | H12: =B12-C12 -> 0.6337623 | I12: =C12-D12 -> 0.066727271 | J12: =D12-E12 -> 0.011023657 | K12: =E12-F12 -> 0.0041967889 | L12: =F12 -> 0.00044020147 | M12: =G12*$B$4+H12*$C$4+I12*$D$4+J12*$E$4+K12*$F$4+L12*$G$4 -> 0.20428926
A13: 30 | B13: =IF($A13<=0,0,_xlfn.NORM.S.DIST((LN($A13)-C$5)/$B$6,TRUE())) -> 0.8134567 | C13: =IF($A13<=0,0,_xlfn.NORM.S.DIST((LN($A13)-D$5)/$B$6,TRUE())) -> 0.14232691 | D13: =IF($A13<=0,0,_xlfn.NORM.S.DIST((LN($A13)-E$5)/$B$6,TRUE())) -> 0.033349058 | E13: =IF($A13<=0,0,_xlfn.NORM.S.DIST((LN($A13)-F$5)/$B$6,TRUE())) -> 0.011229278 | F13: =IF($A13<=0,0,_xlfn.NORM.S.DIST((LN($A13)-G$5)/$B$6,TRUE())) -> 0.0013194974 | G13: =1-B13 -> 0.1865433 | H13: =B13-C13 -> 0.67112979 | I13: =C13-D13 -> 0.10897785 | J13: =D13-E13 -> 0.02211978 | K13: =E13-F13 -> 0.0099097801 | L13: =F13 -> 0.0013194974 | M13: =G13*$B$4+H13*$C$4+I13*$D$4+J13*$E$4+K13*$F$4+L13*$G$4 -> 0.24909951
A14: 40 | B14: =IF($A14<=0,0,_xlfn.NORM.S.DIST((LN($A14)-C$5)/$B$6,TRUE())) -> 0.86805156 | C14: =IF($A14<=0,0,_xlfn.NORM.S.DIST((LN($A14)-D$5)/$B$6,TRUE())) -> 0.19950183 | D14: =IF($A14<=0,0,_xlfn.NORM.S.DIST((LN($A14)-E$5)/$B$6,TRUE())) -> 0.054007276 | E14: =IF($A14<=0,0,_xlfn.NORM.S.DIST((LN($A14)-F$5)/$B$6,TRUE())) -> 0.019891237 | F14: =IF($A14<=0,0,_xlfn.NORM.S.DIST((LN($A14)-G$5)/$B$6,TRUE())) -> 0.0027145163 | G14: =1-B14 -> 0.13194844 | H14: =B14-C14 -> 0.66854973 | I14: =C14-D14 -> 0.14549455 | J14: =D14-E14 -> 0.034116039 | K14: =E14-F14 -> 0.017176721 | L14: =F14 -> 0.0027145163 | M14: =G14*$B$4+H14*$C$4+I14*$D$4+J14*$E$4+K14*$F$4+L14*$G$4 -> 0.2836453
A15: 50 | B15: =IF($A15<=0,0,_xlfn.NORM.S.DIST((LN($A15)-C$5)/$B$6,TRUE())) -> 0.90198262 | C15: =IF($A15<=0,0,_xlfn.NORM.S.DIST((LN($A15)-D$5)/$B$6,TRUE())) -> 0.25216306 | D15: =IF($A15<=0,0,_xlfn.NORM.S.DIST((LN($A15)-E$5)/$B$6,TRUE())) -> 0.076146641 | E15: =IF($A15<=0,0,_xlfn.NORM.S.DIST((LN($A15)-F$5)/$B$6,TRUE())) -> 0.030033816 | F15: =IF($A15<=0,0,_xlfn.NORM.S.DIST((LN($A15)-G$5)/$B$6,TRUE())) -> 0.0045976523 | G15: =1-B15 -> 0.098017376 | H15: =B15-C15 -> 0.64981957 | I15: =C15-D15 -> 0.17601642 | J15: =D15-E15 -> 0.046112825 | K15: =E15-F15 -> 0.025436164 | L15: =F15 -> 0.0045976523 | M15: =G15*$B$4+H15*$C$4+I15*$D$4+J15*$E$4+K15*$F$4+L15*$G$4 -> 0.31253792
A16: 60 | B16: =IF($A16<=0,0,_xlfn.NORM.S.DIST((LN($A16)-C$5)/$B$6,TRUE())) -> 0.92456877 | C16: =IF($A16<=0,0,_xlfn.NORM.S.DIST((LN($A16)-D$5)/$B$6,TRUE())) -> 0.30009123 | D16: =IF($A16<=0,0,_xlfn.NORM.S.DIST((LN($A16)-E$5)/$B$6,TRUE())) -> 0.098887312 | E16: =IF($A16<=0,0,_xlfn.NORM.S.DIST((LN($A16)-F$5)/$B$6,TRUE())) -> 0.04121684 | F16: =IF($A16<=0,0,_xlfn.NORM.S.DIST((LN($A16)-G$5)/$B$6,TRUE())) -> 0.0069246995 | G16: =1-B16 -> 0.075431227 | H16: =B16-C16 -> 0.62447754 | I16: =C16-D16 -> 0.20120392 | J16: =D16-E16 -> 0.057670472 | K16: =E16-F16 -> 0.034292141 | L16: =F16 -> 0.0069246995 | M16: =G16*$B$4+H16*$C$4+I16*$D$4+J16*$E$4+K16*$F$4+L16*$G$4 -> 0.33776183
A17: 70 | B17: =IF($A17<=0,0,_xlfn.NORM.S.DIST((LN($A17)-C$5)/$B$6,TRUE())) -> 0.940368 | C17: =IF($A17<=0,0,_xlfn.NORM.S.DIST((LN($A17)-D$5)/$B$6,TRUE())) -> 0.34356252 | D17: =IF($A17<=0,0,_xlfn.NORM.S.DIST((LN($A17)-E$5)/$B$6,TRUE())) -> 0.12169826 | E17: =IF($A17<=0,0,_xlfn.NORM.S.DIST((LN($A17)-F$5)/$B$6,TRUE())) -> 0.053116587 | F17: =IF($A17<=0,0,_xlfn.NORM.S.DIST((LN($A17)-G$5)/$B$6,TRUE())) -> 0.0096478733 | G17: =1-B17 -> 0.059632002 | H17: =B17-C17 -> 0.59680547 | I17: =C17-D17 -> 0.22186426 | J17: =D17-E17 -> 0.068581672 | K17: =E17-F17 -> 0.043468713 | L17: =F17 -> 0.0096478733 | M17: =G17*$B$4+H17*$C$4+I17*$D$4+J17*$E$4+K17*$F$4+L17*$G$4 -> 0.36033947
A18: 80 | B18: =IF($A18<=0,0,_xlfn.NORM.S.DIST((LN($A18)-C$5)/$B$6,TRUE())) -> 0.95184509 | C18: =IF($A18<=0,0,_xlfn.NORM.S.DIST((LN($A18)-D$5)/$B$6,TRUE())) -> 0.38299782 | D18: =IF($A18<=0,0,_xlfn.NORM.S.DIST((LN($A18)-E$5)/$B$6,TRUE())) -> 0.14425491 | E18: =IF($A18<=0,0,_xlfn.NORM.S.DIST((LN($A18)-F$5)/$B$6,TRUE())) -> 0.065494255 | F18: =IF($A18<=0,0,_xlfn.NORM.S.DIST((LN($A18)-G$5)/$B$6,TRUE())) -> 0.012720999 | G18: =1-B18 -> 0.048154907 | H18: =B18-C18 -> 0.56884728 | I18: =C18-D18 -> 0.23874291 | J18: =D18-E18 -> 0.078760653 | K18: =E18-F18 -> 0.052773256 | L18: =F18 -> 0.012720999 | M18: =G18*$B$4+H18*$C$4+I18*$D$4+J18*$E$4+K18*$F$4+L18*$G$4 -> 0.38087069
A19: 90 | B19: =IF($A19<=0,0,_xlfn.NORM.S.DIST((LN($A19)-C$5)/$B$6,TRUE())) -> 0.96043493 | C19: =IF($A19<=0,0,_xlfn.NORM.S.DIST((LN($A19)-D$5)/$B$6,TRUE())) -> 0.41883518 | D19: =IF($A19<=0,0,_xlfn.NORM.S.DIST((LN($A19)-E$5)/$B$6,TRUE())) -> 0.16635897 | E19: =IF($A19<=0,0,_xlfn.NORM.S.DIST((LN($A19)-F$5)/$B$6,TRUE())) -> 0.078172385 | F19: =IF($A19<=0,0,_xlfn.NORM.S.DIST((LN($A19)-G$5)/$B$6,TRUE())) -> 0.016101483 | G19: =1-B19 -> 0.03956507 | H19: =B19-C19 -> 0.54159975 | I19: =C19-D19 -> 0.2524762 | J19: =D19-E19 -> 0.088186589 | K19: =E19-F19 -> 0.062070902 | L19: =F19 -> 0.016101483 | M19: =G19*$B$4+H19*$C$4+I19*$D$4+J19*$E$4+K19*$F$4+L19*$G$4 -> 0.39974328
A20: 100 | B20: =IF($A20<=0,0,_xlfn.NORM.S.DIST((LN($A20)-C$5)/$B$6,TRUE())) -> 0.96702157 | C20: =IF($A20<=0,0,_xlfn.NORM.S.DIST((LN($A20)-D$5)/$B$6,TRUE())) -> 0.45148387 | D20: =IF($A20<=0,0,_xlfn.NORM.S.DIST((LN($A20)-E$5)/$B$6,TRUE())) -> 0.18789155 | E20: =IF($A20<=0,0,_xlfn.NORM.S.DIST((LN($A20)-F$5)/$B$6,TRUE())) -> 0.091018113 | F20: =IF($A20<=0,0,_xlfn.NORM.S.DIST((LN($A20)-G$5)/$B$6,TRUE())) -> 0.019750898 | G20: =1-B20 -> 0.032978434 | H20: =B20-C20 -> 0.5155377 | I20: =C20-D20 -> 0.26359231 | J20: =D20-E20 -> 0.09687344 | K20: =E20-F20 -> 0.071267215 | L20: =F20 -> 0.019750898 | M20: =G20*$B$4+H20*$C$4+I20*$D$4+J20*$E$4+K20*$F$4+L20*$G$4 -> 0.41722705
A21: 110 | B21: =IF($A21<=0,0,_xlfn.NORM.S.DIST((LN($A21)-C$5)/$B$6,TRUE())) -> 0.97217485 | C21: =IF($A21<=0,0,_xlfn.NORM.S.DIST((LN($A21)-D$5)/$B$6,TRUE())) -> 0.48131007 | D21: =IF($A21<=0,0,_xlfn.NORM.S.DIST((LN($A21)-E$5)/$B$6,TRUE())) -> 0.20878467 | E21: =IF($A21<=0,0,_xlfn.NORM.S.DIST((LN($A21)-F$5)/$B$6,TRUE())) -> 0.10393134 | F21: =IF($A21<=0,0,_xlfn.NORM.S.DIST((LN($A21)-G$5)/$B$6,TRUE())) -> 0.023634959 | G21: =1-B21 -> 0.027825154 | H21: =B21-C21 -> 0.49086477 | I21: =C21-D21 -> 0.2725254 | J21: =D21-E21 -> 0.10485333 | K21: =E21-F21 -> 0.080296383 | L21: =F21 -> 0.023634959 | M21: =G21*$B$4+H21*$C$4+I21*$D$4+J21*$E$4+K21*$F$4+L21*$G$4 -> 0.4335206
... A70: 600 | B70: =IF($A70<=0,0,_xlfn.NORM.S.DIST((LN($A70)-C$5)/$B$6,TRUE())) -> 0.99942206 | C70: =IF($A70<=0,0,_xlfn.NORM.S.DIST((LN($A70)-D$5)/$B$6,TRUE())) -> 0.90128722 | D70: =IF($A70<=0,0,_xlfn.NORM.S.DIST((LN($A70)-E$5)/$B$6,TRUE())) -> 0.70025757 | E70: =IF($A70<=0,0,_xlfn.NORM.S.DIST((LN($A70)-F$5)/$B$6,TRUE())) -> 0.53041876 | F70: =IF($A70<=0,0,_xlfn.NORM.S.DIST((LN($A70)-G$5)/$B$6,TRUE())) -> 0.25846438 | G70: =1-B70 -> 0.00057793693 | H70: =B70-C70 -> 0.098134841 | I70: =C70-D70 -> 0.20102965 | J70: =D70-E70 -> 0.16983881 | K70: =E70-F70 -> 0.27195438 | L70: =F70 -> 0.25846438 | M70: =G70*$B$4+H70*$C$4+I70*$D$4+J70*$E$4+K70*$F$4+L70*$G$4 -> 0.75565097

Sheet 5_卸売・小売業
A1: 卸売・小売業：フラジリティ曲線と損失率曲線
A3: 被害モード | B3: 0 | C3: 1 | D3: 2 | E3: 3 | F3: 4 | G3: 5
A4: 損失率 | B4: =データ!$E$20 -> 0 | C4: =データ!$E$21 -> 0.25 | D4: =データ!$E$22 -> 0.5 | E4: =データ!$E$23 -> 0.75 | F4: =データ!$E$24 -> 0.9 | G4: =データ!$E$25 -> 1
A5: μ | C5: =データ!$F$5 -> 2.05 | D5: =データ!$F$6 -> 4.04 | E5: =データ!$F$7 -> 5.06 | F5: =データ!$F$8 -> 5.61 | G5: =データ!$F$9 -> 6.06
A6: σ | B6: =データ!$F$10 -> 1.51
A9: 浸水深(cm) | B9: 被害モード1以上率 | C9: 被害モード2以上率 | D9: 被害モード3以上率 | E9: 被害モード4以上率 | F9: 被害モード5以上率 | G9: 被害モード0率(無被害) | H9: 被害モード1率 | I9: 被害モード2率 | J9: 被害モード3率 | K9: 被害モード4率 | L9: 被害モード5率 | M9: 損失率
A10: 0 | B10: =IF($A10<=0,0,_xlfn.NORM.S.DIST((LN($A10)-C$5)/$B$6,TRUE())) -> 0 | C10: =IF($A10<=0,0,_xlfn.NORM.S.DIST((LN($A10)-D$5)/$B$6,TRUE())) -> 0 | D10: =IF($A10<=0,0,_xlfn.NORM.S.DIST((LN($A10)-E$5)/$B$6,TRUE())) -> 0 | E10: =IF($A10<=0,0,_xlfn.NORM.S.DIST((LN($A10)-F$5)/$B$6,TRUE())) -> 0 | F10: =IF($A10<=0,0,_xlfn.NORM.S.DIST((LN($A10)-G$5)/$B$6,TRUE())) -> 0 | G10: =1-B10 -> 1 | H10: =B10-C10 -> 0 | I10: =C10-D10 -> 0 | J10: =D10-E10 -> 0 | K10: =E10-F10 -> 0 | L10: =F10 -> 0 | M10: =G10*$B$4+H10*$C$4+I10*$D$4+J10*$E$4+K10*$F$4+L10*$G$4 -> 0
A11: 10 | B11: =IF($A11<=0,0,_xlfn.NORM.S.DIST((LN($A11)-C$5)/$B$6,TRUE())) -> 0.56642312 | C11: =IF($A11<=0,0,_xlfn.NORM.S.DIST((LN($A11)-D$5)/$B$6,TRUE())) -> 0.1249472 | D11: =IF($A11<=0,0,_xlfn.NORM.S.DIST((LN($A11)-E$5)/$B$6,TRUE())) -> 0.033917405 | E11: =IF($A11<=0,0,_xlfn.NORM.S.DIST((LN($A11)-F$5)/$B$6,TRUE())) -> 0.014249758 | F11: =IF($A11<=0,0,_xlfn.NORM.S.DIST((LN($A11)-G$5)/$B$6,TRUE())) -> 0.0064167916 | G11: =1-B11 -> 0.43357688 | H11: =B11-C11 -> 0.44147592 | I11: =C11-D11 -> 0.091029797 | J11: =D11-E11 -> 0.019667647 | K11: =E11-F11 -> 0.0078329662 | L11: =F11 -> 0.0064167916 | M11: =G11*$B$4+H11*$C$4+I11*$D$4+J11*$E$4+K11*$F$4+L11*$G$4 -> 0.18410108
A12: 20 | B12: =IF($A12<=0,0,_xlfn.NORM.S.DIST((LN($A12)-C$5)/$B$6,TRUE())) -> 0.73444509 | C12: =IF($A12<=0,0,_xlfn.NORM.S.DIST((LN($A12)-D$5)/$B$6,TRUE())) -> 0.24460432 | D12: =IF($A12<=0,0,_xlfn.NORM.S.DIST((LN($A12)-E$5)/$B$6,TRUE())) -> 0.08580251 | E12: =IF($A12<=0,0,_xlfn.NORM.S.DIST((LN($A12)-F$5)/$B$6,TRUE())) -> 0.041698857 | F12: =IF($A12<=0,0,_xlfn.NORM.S.DIST((LN($A12)-G$5)/$B$6,TRUE())) -> 0.021213038 | G12: =1-B12 -> 0.26555491 | H12: =B12-C12 -> 0.48984077 | I12: =C12-D12 -> 0.15880181 | J12: =D12-E12 -> 0.044103654 | K12: =E12-F12 -> 0.020485818 | L12: =F12 -> 0.021213038 | M12: =G12*$B$4+H12*$C$4+I12*$D$4+J12*$E$4+K12*$F$4+L12*$G$4 -> 0.27458911
A13: 30 | B13: =IF($A13<=0,0,_xlfn.NORM.S.DIST((LN($A13)-C$5)/$B$6,TRUE())) -> 0.81456174 | C13: =IF($A13<=0,0,_xlfn.NORM.S.DIST((LN($A13)-D$5)/$B$6,TRUE())) -> 0.33613009 | D13: =IF($A13<=0,0,_xlfn.NORM.S.DIST((LN($A13)-E$5)/$B$6,TRUE())) -> 0.13598334 | E13: =IF($A13<=0,0,_xlfn.NORM.S.DIST((LN($A13)-F$5)/$B$6,TRUE())) -> 0.071763357 | F13: =IF($A13<=0,0,_xlfn.NORM.S.DIST((LN($A13)-G$5)/$B$6,TRUE())) -> 0.039136432 | G13: =1-B13 -> 0.18543826 | H13: =B13-C13 -> 0.47843165 | I13: =C13-D13 -> 0.20014675 | J13: =D13-E13 -> 0.06421998 | K13: =E13-F13 -> 0.032626925 | L13: =F13 -> 0.039136432 | M13: =G13*$B$4+H13*$C$4+I13*$D$4+J13*$E$4+K13*$F$4+L13*$G$4 -> 0.33634694
A14: 40 | B14: =IF($A14<=0,0,_xlfn.NORM.S.DIST((LN($A14)-C$5)/$B$6,TRUE())) -> 0.86111681 | C14: =IF($A14<=0,0,_xlfn.NORM.S.DIST((LN($A14)-D$5)/$B$6,TRUE())) -> 0.40806313 | D14: =IF($A14<=0,0,_xlfn.NORM.S.DIST((LN($A14)-E$5)/$B$6,TRUE())) -> 0.18193202 | E14: =IF($A14<=0,0,_xlfn.NORM.S.DIST((LN($A14)-F$5)/$B$6,TRUE())) -> 0.10163944 | F14: =IF($A14<=0,0,_xlfn.NORM.S.DIST((LN($A14)-G$5)/$B$6,TRUE())) -> 0.058175166 | G14: =1-B14 -> 0.13888319 | H14: =B14-C14 -> 0.45305367 | I14: =C14-D14 -> 0.22613111 | J14: =D14-E14 -> 0.080292574 | K14: =E14-F14 -> 0.043464277 | L14: =F14 -> 0.058175166 | M14: =G14*$B$4+H14*$C$4+I14*$D$4+J14*$E$4+K14*$F$4+L14*$G$4 -> 0.38384142
A15: 50 | B15: =IF($A15<=0,0,_xlfn.NORM.S.DIST((LN($A15)-C$5)/$B$6,TRUE())) -> 0.89123596 | C15: =IF($A15<=0,0,_xlfn.NORM.S.DIST((LN($A15)-D$5)/$B$6,TRUE())) -> 0.46622889 | D15: =IF($A15<=0,0,_xlfn.NORM.S.DIST((LN($A15)-E$5)/$B$6,TRUE())) -> 0.22355268 | E15: =IF($A15<=0,0,_xlfn.NORM.S.DIST((LN($A15)-F$5)/$B$6,TRUE())) -> 0.13040301 | F15: =IF($A15<=0,0,_xlfn.NORM.S.DIST((LN($A15)-G$5)/$B$6,TRUE())) -> 0.077440384 | G15: =1-B15 -> 0.10876404 | H15: =B15-C15 -> 0.42500707 | I15: =C15-D15 -> 0.24267621 | J15: =D15-E15 -> 0.093149668 | K15: =E15-F15 -> 0.052962629 | L15: =F15 -> 0.077440384 | M15: =G15*$B$4+H15*$C$4+I15*$D$4+J15*$E$4+K15*$F$4+L15*$G$4 -> 0.42255887
A16: 60 | B16: =IF($A16<=0,0,_xlfn.NORM.S.DIST((LN($A16)-C$5)/$B$6,TRUE())) -> 0.91211116 | C16: =IF($A16<=0,0,_xlfn.NORM.S.DIST((LN($A16)-D$5)/$B$6,TRUE())) -> 0.51435474 | D16: =IF($A16<=0,0,_xlfn.NORM.S.DIST((LN($A16)-E$5)/$B$6,TRUE())) -> 0.26124661 | E16: =IF($A16<=0,0,_xlfn.NORM.S.DIST((LN($A16)-F$5)/$B$6,TRUE())) -> 0.15775069 | F16: =IF($A16<=0,0,_xlfn.NORM.S.DIST((LN($A16)-G$5)/$B$6,TRUE())) -> 0.096499466 | G16: =1-B16 -> 0.087888837 | H16: =B16-C16 -> 0.39775642 | I16: =C16-D16 -> 0.25310814 | J16: =D16-E16 -> 0.10349592 | K16: =E16-F16 -> 0.061251227 | L16: =F16 -> 0.096499466 | M16: =G16*$B$4+H16*$C$4+I16*$D$4+J16*$E$4+K16*$F$4+L16*$G$4 -> 0.45524068
A17: 70 | B17: =IF($A17<=0,0,_xlfn.NORM.S.DIST((LN($A17)-C$5)/$B$6,TRUE())) -> 0.92729776 | C17: =IF($A17<=0,0,_xlfn.NORM.S.DIST((LN($A17)-D$5)/$B$6,TRUE())) -> 0.55490995 | D17: =IF($A17<=0,0,_xlfn.NORM.S.DIST((LN($A17)-E$5)/$B$6,TRUE())) -> 0.29548864 | E17: =IF($A17<=0,0,_xlfn.NORM.S.DIST((LN($A17)-F$5)/$B$6,TRUE())) -> 0.18361908 | F17: =IF($A17<=0,0,_xlfn.NORM.S.DIST((LN($A17)-G$5)/$B$6,TRUE())) -> 0.11513337 | G17: =1-B17 -> 0.072702238 | H17: =B17-C17 -> 0.37238781 | I17: =C17-D17 -> 0.25942131 | J17: =D17-E17 -> 0.11186956 | K17: =E17-F17 -> 0.068485707 | L17: =F17 -> 0.11513337 | M17: =G17*$B$4+H17*$C$4+I17*$D$4+J17*$E$4+K17*$F$4+L17*$G$4 -> 0.48348029
A18: 80 | B18: =IF($A18<=0,0,_xlfn.NORM.S.DIST((LN($A18)-C$5)/$B$6,TRUE())) -> 0.93875288 | C18: =IF($A18<=0,0,_xlfn.NORM.S.DIST((LN($A18)-D$5)/$B$6,TRUE())) -> 0.58959672 | D18: =IF($A18<=0,0,_xlfn.NORM.S.DIST((LN($A18)-E$5)/$B$6,TRUE())) -> 0.3267198 | E18: =IF($A18<=0,0,_xlfn.NORM.S.DIST((LN($A18)-F$5)/$B$6,TRUE())) -> 0.20804385 | F18: =IF($A18<=0,0,_xlfn.NORM.S.DIST((LN($A18)-G$5)/$B$6,TRUE())) -> 0.13323239 | G18: =1-B18 -> 0.061247122 | H18: =B18-C18 -> 0.34915616 | I18: =C18-D18 -> 0.26287691 | J18: =D18-E18 -> 0.11867595 | K18: =E18-F18 -> 0.074811457 | L18: =F18 -> 0.13323239 | M18: =G18*$B$4+H18*$C$4+I18*$D$4+J18*$E$4+K18*$F$4+L18*$G$4 -> 0.50829717
A19: 90 | B19: =IF($A19<=0,0,_xlfn.NORM.S.DIST((LN($A19)-C$5)/$B$6,TRUE())) -> 0.94764012 | C19: =IF($A19<=0,0,_xlfn.NORM.S.DIST((LN($A19)-D$5)/$B$6,TRUE())) -> 0.6196302 | D19: =IF($A19<=0,0,_xlfn.NORM.S.DIST((LN($A19)-E$5)/$B$6,TRUE())) -> 0.35532362 | E19: =IF($A19<=0,0,_xlfn.NORM.S.DIST((LN($A19)-F$5)/$B$6,TRUE())) -> 0.23110112 | F19: =IF($A19<=0,0,_xlfn.NORM.S.DIST((LN($A19)-G$5)/$B$6,TRUE())) -> 0.15074612 | G19: =1-B19 -> 0.05235988 | H19: =B19-C19 -> 0.32800992 | I19: =C19-D19 -> 0.26430659 | J19: =D19-E19 -> 0.1242225 | K19: =E19-F19 -> 0.080355001 | L19: =F19 -> 0.15074612 | M19: =G19*$B$4+H19*$C$4+I19*$D$4+J19*$E$4+K19*$F$4+L19*$G$4 -> 0.53038827
A20: 100 | B20: =IF($A20<=0,0,_xlfn.NORM.S.DIST((LN($A20)-C$5)/$B$6,TRUE())) -> 0.95469281 | C20: =IF($A20<=0,0,_xlfn.NORM.S.DIST((LN($A20)-D$5)/$B$6,TRUE())) -> 0.64590381 | D20: =IF($A20<=0,0,_xlfn.NORM.S.DIST((LN($A20)-E$5)/$B$6,TRUE())) -> 0.3816265 | E20: =IF($A20<=0,0,_xlfn.NORM.S.DIST((LN($A20)-F$5)/$B$6,TRUE())) -> 0.25288129 | F20: =IF($A20<=0,0,_xlfn.NORM.S.DIST((LN($A20)-G$5)/$B$6,TRUE())) -> 0.1676575 | G20: =1-B20 -> 0.045307194 | H20: =B20-C20 -> 0.30878899 | I20: =C20-D20 -> 0.26427732 | J20: =D20-E20 -> 0.12874521 | K20: =E20-F20 -> 0.085223792 | L20: =F20 -> 0.1676575 | M20: =G20*$B$4+H20*$C$4+I20*$D$4+J20*$E$4+K20*$F$4+L20*$G$4 -> 0.55025372
A21: 110 | B21: =IF($A21<=0,0,_xlfn.NORM.S.DIST((LN($A21)-C$5)/$B$6,TRUE())) -> 0.96039472 | C21: =IF($A21<=0,0,_xlfn.NORM.S.DIST((LN($A21)-D$5)/$B$6,TRUE())) -> 0.66909089 | D21: =IF($A21<=0,0,_xlfn.NORM.S.DIST((LN($A21)-E$5)/$B$6,TRUE())) -> 0.40590469 | E21: =IF($A21<=0,0,_xlfn.NORM.S.DIST((LN($A21)-F$5)/$B$6,TRUE())) -> 0.27347695 | F21: =IF($A21<=0,0,_xlfn.NORM.S.DIST((LN($A21)-G$5)/$B$6,TRUE())) -> 0.18396857 | G21: =1-B21 -> 0.039605285 | H21: =B21-C21 -> 0.29130383 | I21: =C21-D21 -> 0.2631862 | J21: =D21-E21 -> 0.13242773 | K21: =E21-F21 -> 0.089508382 | L21: =F21 -> 0.18396857 | M21: =G21*$B$4+H21*$C$4+I21*$D$4+J21*$E$4+K21*$F$4+L21*$G$4 -> 0.56826597
... A70: 600 | B70: =IF($A70<=0,0,_xlfn.NORM.S.DIST((LN($A70)-C$5)/$B$6,TRUE())) -> 0.9980038 | C70: =IF($A70<=0,0,_xlfn.NORM.S.DIST((LN($A70)-D$5)/$B$6,TRUE())) -> 0.94072403 | D70: =IF($A70<=0,0,_xlfn.NORM.S.DIST((LN($A70)-E$5)/$B$6,TRUE())) -> 0.81202519 | E70: =IF($A70<=0,0,_xlfn.NORM.S.DIST((LN($A70)-F$5)/$B$6,TRUE())) -> 0.69886728 | F70: =IF($A70<=0,0,_xlfn.NORM.S.DIST((LN($A70)-G$5)/$B$6,TRUE())) -> 0.5882837 | G70: =1-B70 -> 0.0019962016 | H70: =B70-C70 -> 0.057279765 | I70: =C70-D70 -> 0.12869885 | J70: =D70-E70 -> 0.11315791 | K70: =E70-F70 -> 0.11058358 | L70: =F70 -> 0.5882837 | M70: =G70*$B$4+H70*$C$4+I70*$D$4+J70*$E$4+K70*$F$4+L70*$G$4 -> 0.85134672

Sheet 6_サービス業
A1: サービス業：フラジリティ曲線と損失率曲線
A3: 被害モード | B3: 0 | C3: 1 | D3: 2 | E3: 3 | F3: 4 | G3: 5
A4: 損失率 | B4: =データ!$E$20 -> 0 | C4: =データ!$E$21 -> 0.25 | D4: =データ!$E$22 -> 0.5 | E4: =データ!$E$23 -> 0.75 | F4: =データ!$E$24 -> 0.9 | G4: =データ!$E$25 -> 1
A5: μ | C5: =データ!$G$5 -> -0.08 | D5: =データ!$G$6 -> 4.46 | E5: =データ!$G$7 -> 6.22 | F5: =データ!$G$8 -> 6.62 | G5: =データ!$G$9 -> 8.47
A6: σ | B6: =データ!$G$10 -> 2.66
A9: 浸水深(cm) | B9: 被害モード1以上率 | C9: 被害モード2以上率 | D9: 被害モード3以上率 | E9: 被害モード4以上率 | F9: 被害モード5以上率 | G9: 被害モード0率(無被害) | H9: 被害モード1率 | I9: 被害モード2率 | J9: 被害モード3率 | K9: 被害モード4率 | L9: 被害モード5率 | M9: 損失率
A10: 0 | B10: =IF($A10<=0,0,_xlfn.NORM.S.DIST((LN($A10)-C$5)/$B$6,TRUE())) -> 0 | C10: =IF($A10<=0,0,_xlfn.NORM.S.DIST((LN($A10)-D$5)/$B$6,TRUE())) -> 0 | D10: =IF($A10<=0,0,_xlfn.NORM.S.DIST((LN($A10)-E$5)/$B$6,TRUE())) -> 0 | E10: =IF($A10<=0,0,_xlfn.NORM.S.DIST((LN($A10)-F$5)/$B$6,TRUE())) -> 0 | F10: =IF($A10<=0,0,_xlfn.NORM.S.DIST((LN($A10)-G$5)/$B$6,TRUE())) -> 0 | G10: =1-B10 -> 1 | H10: =B10-C10 -> 0 | I10: =C10-D10 -> 0 | J10: =D10-E10 -> 0 | K10: =E10-F10 -> 0 | L10: =F10 -> 0 | M10: =G10*$B$4+H10*$C$4+I10*$D$4+J10*$E$4+K10*$F$4+L10*$G$4 -> 0
A11: 10 | B11: =IF($A11<=0,0,_xlfn.NORM.S.DIST((LN($A11)-C$5)/$B$6,TRUE())) -> 0.81479581 | C11: =IF($A11<=0,0,_xlfn.NORM.S.DIST((LN($A11)-D$5)/$B$6,TRUE())) -> 0.20866611 | D11: =IF($A11<=0,0,_xlfn.NORM.S.DIST((LN($A11)-E$5)/$B$6,TRUE())) -> 0.070414305 | E11: =IF($A11<=0,0,_xlfn.NORM.S.DIST((LN($A11)-F$5)/$B$6,TRUE())) -> 0.052285264 | F11: =IF($A11<=0,0,_xlfn.NORM.S.DIST((LN($A11)-G$5)/$B$6,TRUE())) -> 0.010208991 | G11: =1-B11 -> 0.18520419 | H11: =B11-C11 -> 0.6061297 | I11: =C11-D11 -> 0.13825181 | J11: =D11-E11 -> 0.018129041 | K11: =E11-F11 -> 0.042076273 | L11: =F11 -> 0.010208991 | M11: =G11*$B$4+H11*$C$4+I11*$D$4+J11*$E$4+K11*$F$4+L11*$G$4 -> 0.28233275
A12: 20 | B12: =IF($A12<=0,0,_xlfn.NORM.S.DIST((LN($A12)-C$5)/$B$6,TRUE())) -> 0.87621879 | C12: =IF($A12<=0,0,_xlfn.NORM.S.DIST((LN($A12)-D$5)/$B$6,TRUE())) -> 0.29099626 | D12: =IF($A12<=0,0,_xlfn.NORM.S.DIST((LN($A12)-E$5)/$B$6,TRUE())) -> 0.11273117 | E12: =IF($A12<=0,0,_xlfn.NORM.S.DIST((LN($A12)-F$5)/$B$6,TRUE())) -> 0.086519021 | F12: =IF($A12<=0,0,_xlfn.NORM.S.DIST((LN($A12)-G$5)/$B$6,TRUE())) -> 0.019795288 | G12: =1-B12 -> 0.12378121 | H12: =B12-C12 -> 0.58522252 | I12: =C12-D12 -> 0.17826509 | J12: =D12-E12 -> 0.026212151 | K12: =E12-F12 -> 0.066723733 | L12: =F12 -> 0.019795288 | M12: =G12*$B$4+H12*$C$4+I12*$D$4+J12*$E$4+K12*$F$4+L12*$G$4 -> 0.33494394
A13: 30 | B13: =IF($A13<=0,0,_xlfn.NORM.S.DIST((LN($A13)-C$5)/$B$6,TRUE())) -> 0.90468553 | C13: =IF($A13<=0,0,_xlfn.NORM.S.DIST((LN($A13)-D$5)/$B$6,TRUE())) -> 0.3452981 | D13: =IF($A13<=0,0,_xlfn.NORM.S.DIST((LN($A13)-E$5)/$B$6,TRUE())) -> 0.1446405 | E13: =IF($A13<=0,0,_xlfn.NORM.S.DIST((LN($A13)-F$5)/$B$6,TRUE())) -> 0.11312483 | F13: =IF($A13<=0,0,_xlfn.NORM.S.DIST((LN($A13)-G$5)/$B$6,TRUE())) -> 0.02835334 | G13: =1-B13 -> 0.095314468 | H13: =B13-C13 -> 0.55938743 | I13: =C13-D13 -> 0.2006576 | J13: =D13-E13 -> 0.031515666 | K13: =E13-F13 -> 0.084771492 | L13: =F13 -> 0.02835334 | M13: =G13*$B$4+H13*$C$4+I13*$D$4+J13*$E$4+K13*$F$4+L13*$G$4 -> 0.36846009
A14: 40 | B14: =IF($A14<=0,0,_xlfn.NORM.S.DIST((LN($A14)-C$5)/$B$6,TRUE())) -> 0.92173982 | C14: =IF($A14<=0,0,_xlfn.NORM.S.DIST((LN($A14)-D$5)/$B$6,TRUE())) -> 0.38594831 | D14: =IF($A14<=0,0,_xlfn.NORM.S.DIST((LN($A14)-E$5)/$B$6,TRUE())) -> 0.17066286 | E14: =IF($A14<=0,0,_xlfn.NORM.S.DIST((LN($A14)-F$5)/$B$6,TRUE())) -> 0.13524714 | F14: =IF($A14<=0,0,_xlfn.NORM.S.DIST((LN($A14)-G$5)/$B$6,TRUE())) -> 0.036134981 | G14: =1-B14 -> 0.078260181 | H14: =B14-C14 -> 0.53579151 | I14: =C14-D14 -> 0.21528545 | J14: =D14-E14 -> 0.035415723 | K14: =E14-F14 -> 0.099112155 | L14: =F14 -> 0.036134981 | M14: =G14*$B$4+H14*$C$4+I14*$D$4+J14*$E$4+K14*$F$4+L14*$G$4 -> 0.39348831
A15: 50 | B15: =IF($A15<=0,0,_xlfn.NORM.S.DIST((LN($A15)-C$5)/$B$6,TRUE())) -> 0.93329124 | C15: =IF($A15<=0,0,_xlfn.NORM.S.DIST((LN($A15)-D$5)/$B$6,TRUE())) -> 0.41839296 | D15: =IF($A15<=0,0,_xlfn.NORM.S.DIST((LN($A15)-E$5)/$B$6,TRUE())) -> 0.1927901 | E15: =IF($A15<=0,0,_xlfn.NORM.S.DIST((LN($A15)-F$5)/$B$6,TRUE())) -> 0.15433031 | F15: =IF($A15<=0,0,_xlfn.NORM.S.DIST((LN($A15)-G$5)/$B$6,TRUE())) -> 0.043307982 | G15: =1-B15 -> 0.066708756 | H15: =B15-C15 -> 0.51489828 | I15: =C15-D15 -> 0.22560286 | J15: =D15-E15 -> 0.038459787 | K15: =E15-F15 -> 0.11102233 | L15: =F15 -> 0.043307982 | M15: =G15*$B$4+H15*$C$4+I15*$D$4+J15*$E$4+K15*$F$4+L15*$G$4 -> 0.41359892
A16: 60 | B16: =IF($A16<=0,0,_xlfn.NORM.S.DIST((LN($A16)-C$5)/$B$6,TRUE())) -> 0.94171126 | C16: =IF($A16<=0,0,_xlfn.NORM.S.DIST((LN($A16)-D$5)/$B$6,TRUE())) -> 0.44533185 | D16: =IF($A16<=0,0,_xlfn.NORM.S.DIST((LN($A16)-E$5)/$B$6,TRUE())) -> 0.21211083 | E16: =IF($A16<=0,0,_xlfn.NORM.S.DIST((LN($A16)-F$5)/$B$6,TRUE())) -> 0.17118458 | F16: =IF($A16<=0,0,_xlfn.NORM.S.DIST((LN($A16)-G$5)/$B$6,TRUE())) -> 0.049986633 | G16: =1-B16 -> 0.058288739 | H16: =B16-C16 -> 0.49637942 | I16: =C16-D16 -> 0.23322102 | J16: =D16-E16 -> 0.040926249 | K16: =E16-F16 -> 0.12119794 | L16: =F16 -> 0.049986633 | M16: =G16*$B$4+H16*$C$4+I16*$D$4+J16*$E$4+K16*$F$4+L16*$G$4 -> 0.43046483
A17: 70 | B17: =IF($A17<=0,0,_xlfn.NORM.S.DIST((LN($A17)-C$5)/$B$6,TRUE())) -> 0.9481584 | C17: =IF($A17<=0,0,_xlfn.NORM.S.DIST((LN($A17)-D$5)/$B$6,TRUE())) -> 0.46831227 | D17: =IF($A17<=0,0,_xlfn.NORM.S.DIST((LN($A17)-E$5)/$B$6,TRUE())) -> 0.22929603 | E17: =IF($A17<=0,0,_xlfn.NORM.S.DIST((LN($A17)-F$5)/$B$6,TRUE())) -> 0.18631893 | F17: =IF($A17<=0,0,_xlfn.NORM.S.DIST((LN($A17)-G$5)/$B$6,TRUE())) -> 0.056252714 | G17: =1-B17 -> 0.051841597 | H17: =B17-C17 -> 0.47984613 | I17: =C17-D17 -> 0.23901624 | J17: =D17-E17 -> 0.042977105 | K17: =E17-F17 -> 0.13006621 | L17: =F17 -> 0.056252714 | M17: =G17*$B$4+H17*$C$4+I17*$D$4+J17*$E$4+K17*$F$4+L17*$G$4 -> 0.44501479
A18: 80 | B18: =IF($A18<=0,0,_xlfn.NORM.S.DIST((LN($A18)-C$5)/$B$6,TRUE())) -> 0.95327309 | C18: =IF($A18<=0,0,_xlfn.NORM.S.DIST((LN($A18)-D$5)/$B$6,TRUE())) -> 0.48830736 | D18: =IF($A18<=0,0,_xlfn.NORM.S.DIST((LN($A18)-E$5)/$B$6,TRUE())) -> 0.244793 | E18: =IF($A18<=0,0,_xlfn.NORM.S.DIST((LN($A18)-F$5)/$B$6,TRUE())) -> 0.2000778 | F18: =IF($A18<=0,0,_xlfn.NORM.S.DIST((LN($A18)-G$5)/$B$6,TRUE())) -> 0.062167216 | G18: =1-B18 -> 0.046726906 | H18: =B18-C18 -> 0.46496573 | I18: =C18-D18 -> 0.24351436 | J18: =D18-E18 -> 0.044715204 | K18: =E18-F18 -> 0.13791058 | L18: =F18 -> 0.062167216 | M18: =G18*$B$4+H18*$C$4+I18*$D$4+J18*$E$4+K18*$F$4+L18*$G$4 -> 0.45782176
A19: 90 | B19: =IF($A19<=0,0,_xlfn.NORM.S.DIST((LN($A19)-C$5)/$B$6,TRUE())) -> 0.95744105 | C19: =IF($A19<=0,0,_xlfn.NORM.S.DIST((LN($A19)-D$5)/$B$6,TRUE())) -> 0.50597036 | D19: =IF($A19<=0,0,_xlfn.NORM.S.DIST((LN($A19)-E$5)/$B$6,TRUE())) -> 0.25891692 | E19: =IF($A19<=0,0,_xlfn.NORM.S.DIST((LN($A19)-F$5)/$B$6,TRUE())) -> 0.21270692 | F19: =IF($A19<=0,0,_xlfn.NORM.S.DIST((LN($A19)-G$5)/$B$6,TRUE())) -> 0.067777149 | G19: =1-B19 -> 0.042558952 | H19: =B19-C19 -> 0.45147068 | I19: =C19-D19 -> 0.24705345 | J19: =D19-E19 -> 0.046209994 | K19: =E19-F19 -> 0.14492977 | L19: =F19 -> 0.067777149 | M19: =G19*$B$4+H19*$C$4+I19*$D$4+J19*$E$4+K19*$F$4+L19*$G$4 -> 0.46926583
A20: 100 | B20: =IF($A20<=0,0,_xlfn.NORM.S.DIST((LN($A20)-C$5)/$B$6,TRUE())) -> 0.96090975 | C20: =IF($A20<=0,0,_xlfn.NORM.S.DIST((LN($A20)-D$5)/$B$6,TRUE())) -> 0.52176157 | D20: =IF($A20<=0,0,_xlfn.NORM.S.DIST((LN($A20)-E$5)/$B$6,TRUE())) -> 0.27189928 | E20: =IF($A20<=0,0,_xlfn.NORM.S.DIST((LN($A20)-F$5)/$B$6,TRUE())) -> 0.22438871 | F20: =IF($A20<=0,0,_xlfn.NORM.S.DIST((LN($A20)-G$5)/$B$6,TRUE())) -> 0.073119715 | G20: =1-B20 -> 0.039090253 | H20: =B20-C20 -> 0.43914817 | I20: =C20-D20 -> 0.24986229 | J20: =D20-E20 -> 0.047510571 | K20: =E20-F20 -> 0.151269 | L20: =F20 -> 0.073119715 | M20: =G20*$B$4+H20*$C$4+I20*$D$4+J20*$E$4+K20*$F$4+L20*$G$4 -> 0.47961293
A21: 110 | B21: =IF($A21<=0,0,_xlfn.NORM.S.DIST((LN($A21)-C$5)/$B$6,TRUE())) -> 0.96384593 | C21: =IF($A21<=0,0,_xlfn.NORM.S.DIST((LN($A21)-D$5)/$B$6,TRUE())) -> 0.53601777 | D21: =IF($A21<=0,0,_xlfn.NORM.S.DIST((LN($A21)-E$5)/$B$6,TRUE())) -> 0.28391578 | E21: =IF($A21<=0,0,_xlfn.NORM.S.DIST((LN($A21)-F$5)/$B$6,TRUE())) -> 0.23526286 | F21: =IF($A21<=0,0,_xlfn.NORM.S.DIST((LN($A21)-G$5)/$B$6,TRUE())) -> 0.078224998 | G21: =1-B21 -> 0.036154074 | H21: =B21-C21 -> 0.42782816 | I21: =C21-D21 -> 0.25210199 | J21: =D21-E21 -> 0.048652915 | K21: =E21-F21 -> 0.15703787 | L21: =F21 -> 0.078224998 | M21: =G21*$B$4+H21*$C$4+I21*$D$4+J21*$E$4+K21*$F$4+L21*$G$4 -> 0.4890568
... A70: 600 | B70: =IF($A70<=0,0,_xlfn.NORM.S.DIST((LN($A70)-C$5)/$B$6,TRUE())) -> 0.99255279 | C70: =IF($A70<=0,0,_xlfn.NORM.S.DIST((LN($A70)-D$5)/$B$6,TRUE())) -> 0.76674494 | D70: =IF($A70<=0,0,_xlfn.NORM.S.DIST((LN($A70)-E$5)/$B$6,TRUE())) -> 0.52651606 | E70: =IF($A70<=0,0,_xlfn.NORM.S.DIST((LN($A70)-F$5)/$B$6,TRUE())) -> 0.46658346 | F70: =IF($A70<=0,0,_xlfn.NORM.S.DIST((LN($A70)-G$5)/$B$6,TRUE())) -> 0.21788686 | G70: =1-B70 -> 0.0074472127 | H70: =B70-C70 -> 0.22580784 | I70: =C70-D70 -> 0.24022889 | J70: =D70-E70 -> 0.059932594 | K70: =E70-F70 -> 0.2486966 | L70: =F70 -> 0.21788686 | M70: =G70*$B$4+H70*$C$4+I70*$D$4+J70*$E$4+K70*$F$4+L70*$G$4 -> 0.66322965

Sheet 7_被害関数
A1: 被害関数（浸水深－復旧費用率の期待値）：被害区分の最大値を使用
A2: 損失率 = Σ(被害モードkとなる確率 × 被害区分の最大値)。非製造業の被害モード4は90%。
A4: 浸水深(cm) | B4: 製造業 | C4: 生活関連型産業 | D4: 基礎素材型産業 | E4: 非製造業 | F4: 卸売・小売業 | G4: サービス業
A5: 0 | B5: ='1_製造業'!I10 -> 0 | C5: ='2_生活関連型産業'!I10 -> 0 | D5: ='3_基礎素材型産業'!I10 -> 0 | E5: ='4_非製造業'!M10 -> 0 | F5: ='5_卸売・小売業'!M10 -> 0 | G5: ='6_サービス業'!M10 -> 0
A6: 10 | B6: ='1_製造業'!I11 -> 0.042142906 | C6: ='2_生活関連型産業'!I11 -> 0.032249365 | D6: ='3_基礎素材型産業'!I11 -> 0.077600396 | E6: ='4_非製造業'!M11 -> 0.13518177 | F6: ='5_卸売・小売業'!M11 -> 0.18410108 | G6: ='6_サービス業'!M11 -> 0.28233275
A7: 20 | B7: ='1_製造業'!I12 -> 0.10917914 | C7: ='2_生活関連型産業'!I12 -> 0.085685572 | D7: ='3_基礎素材型産業'!I12 -> 0.1598618 | E7: ='4_非製造業'!M12 -> 0.20428926 | F7: ='5_卸売・小売業'!M12 -> 0.27458911 | G7: ='6_サービス業'!M12 -> 0.33494394
A8: 30 | B8: ='1_製造業'!I13 -> 0.15967849 | C8: ='2_生活関連型産業'!I13 -> 0.13263755 | D8: ='3_基礎素材型産業'!I13 -> 0.20743854 | E8: ='4_非製造業'!M13 -> 0.24909951 | F8: ='5_卸売・小売業'!M13 -> 0.33634694 | G8: ='6_サービス業'!M13 -> 0.36846009
A9: 40 | B9: ='1_製造業'!I14 -> 0.1974463 | C9: ='2_生活関連型産業'!I14 -> 0.1721775 | D9: ='3_基礎素材型産業'!I14 -> 0.23998752 | E9: ='4_非製造業'!M14 -> 0.2836453 | F9: ='5_卸売・小売業'!M14 -> 0.38384142 | G9: ='6_サービス業'!M14 -> 0.39348831
A10: 50 | B10: ='1_製造業'!I15 -> 0.22764058 | C10: ='2_生活関連型産業'!I15 -> 0.20595302 | D10: ='3_基礎素材型産業'!I15 -> 0.26687871 | E10: ='4_非製造業'!M15 -> 0.31253792 | F10: ='5_卸売・小売業'!M15 -> 0.42255887 | G10: ='6_サービス業'!M15 -> 0.41359892
A11: 60 | B11: ='1_製造業'!I16 -> 0.2533845 | C11: ='2_生活関連型産業'!I16 -> 0.23541139 | D11: ='3_基礎素材型産業'!I16 -> 0.29180859 | E11: ='4_非製造業'!M16 -> 0.33776183 | F11: ='5_卸売・小売業'!M16 -> 0.45524068 | G11: ='6_サービス業'!M16 -> 0.43046483
A12: 70 | B12: ='1_製造業'!I17 -> 0.27641547 | C12: ='2_生活関連型産業'!I17 -> 0.26159431 | D12: ='3_基礎素材型産業'!I17 -> 0.31613484 | E12: ='4_非製造業'!M17 -> 0.36033947 | F12: ='5_卸売・小売業'!M17 -> 0.48348029 | G12: ='6_サービス業'!M17 -> 0.44501479
A13: 80 | B13: ='1_製造業'!I18 -> 0.29769492 | C13: ='2_生活関連型産業'!I18 -> 0.28523232 | D13: ='3_基礎素材型産業'!I18 -> 0.34027169 | E13: ='4_非製造業'!M18 -> 0.38087069 | F13: ='5_卸売・小売業'!M18 -> 0.50829717 | G13: ='6_サービス業'!M18 -> 0.45782176
A14: 90 | B14: ='1_製造業'!I19 -> 0.31776094 | C14: ='2_生活関連型産業'!I19 -> 0.30684293 | D14: ='3_基礎素材型産業'!I19 -> 0.36426145 | E14: ='4_非製造業'!M19 -> 0.39974328 | F14: ='5_卸売・小売業'!M19 -> 0.53038827 | G14: ='6_サービス業'!M19 -> 0.46926583
A15: 100 | B15: ='1_製造業'!I20 -> 0.33691912 | C15: ='2_生活関連型産業'!I20 -> 0.32680012 | D15: ='3_基礎素材型産業'!I20 -> 0.38801275 | E15: ='4_非製造業'!M20 -> 0.41722705 | F15: ='5_卸売・小売業'!M20 -> 0.55025372 | G15: ='6_サービス業'!M20 -> 0.47961293
A16: 110 | B16: ='1_製造業'!I21 -> 0.35534564 | C16: ='2_生活関連型産業'!I21 -> 0.34538018 | D16: ='3_基礎素材型産業'!I21 -> 0.4114001 | E16: ='4_非製造業'!M21 -> 0.4335206 | F16: ='5_卸売・小売業'!M21 -> 0.56826597 | G16: ='6_サービス業'!M21 -> 0.4890568
... A65: 600 | B65: ='1_製造業'!I70 -> 0.81012129 | C65: ='2_生活関連型産業'!I70 -> 0.74241062 | D65: ='3_基礎素材型産業'!I70 -> 0.90407017 | E65: ='4_非製造業'!M70 -> 0.75565097 | F65: ='5_卸売・小売業'!M70 -> 0.85134672 | G65: ='6_サービス業'!M70 -> 0.66322965

Sheet 8_参考_論文図3-4再現
A1: 参考：被害区分の中央値を使用した場合（黒田(2024) 図3-4の再現確認用）
A2: 中央値：12.5%, 37.5%, 62.5%(非製造業モード3) / 75%(製造業モード3), 87.5%, 100%。
A4: 浸水深(cm) | B4: 製造業 | C4: 生活関連型産業 | D4: 基礎素材型産業 | E4: 非製造業 | F4: 卸売・小売業 | G4: サービス業
A5: 0 | B5: =IF($A5<=0,0,0.125*_xlfn.NORM.S.DIST((LN($A5)-データ!$B$5)/データ!$B$10,TRUE())+0.25*_xlfn.NORM.S.DIST((LN($A5)-データ!$B$6)/データ!$B$10,TRUE())+0.375*_xlfn.NORM.S.DIST((LN($A5)-データ!$B$7)/データ!$B$10,TRUE())) -> 0 | C5: =IF($A5<=0,0,0.125*_xlfn.NORM.S.DIST((LN($A5)-データ!$C$5)/データ!$C$10,TRUE())+0.25*_xlfn.NORM.S.DIST((LN($A5)-データ!$C$6)/データ!$C$10,TRUE())+0.375*_xlfn.NORM.S.DIST((LN($A5)-データ!$C$7)/データ!$C$10,TRUE())) -> 0 | D5: =IF($A5<=0,0,0.125*_xlfn.NORM.S.DIST((LN($A5)-データ!$D$5)/データ!$D$10,TRUE())+0.25*_xlfn.NORM.S.DIST((LN($A5)-データ!$D$6)/データ!$D$10,TRUE())+0.375*_xlfn.NORM.S.DIST((LN($A5)-データ!$D$7)/データ!$D$10,TRUE())) -> 0 | E5: =IF($A5<=0,0,0.125*_xlfn.NORM.S.DIST((LN($A5)-データ!$E$5)/データ!$E$10,TRUE())+0.25*_xlfn.NORM.S.DIST((LN($A5)-データ!$E$6)/データ!$E$10,TRUE())+0.25*_xlfn.NORM.S.DIST((LN($A5)-データ!$E$7)/データ!$E$10,TRUE())+0.25*_xlfn.NORM.S.DIST((LN($A5)-データ!$E$8)/データ!$E$10,TRUE())+0.125*_xlfn.NORM.S.DIST((LN($A5)-データ!$E$9)/データ!$E$10,TRUE())) -> 0 | F5: =IF($A5<=0,0,0.125*_xlfn.NORM.S.DIST((LN($A5)-データ!$F$5)/データ!$F$10,TRUE())+0.25*_xlfn.NORM.S.DIST((LN($A5)-データ!$F$6)/データ!$F$10,TRUE())+0.25*_xlfn.NORM.S.DIST((LN($A5)-データ!$F$7)/データ!$F$10,TRUE())+0.25*_xlfn.NORM.S.DIST((LN($A5)-データ!$F$8)/データ!$F$10,TRUE())+0.125*_xlfn.NORM.S.DIST((LN($A5)-データ!$F$9)/データ!$F$10,TRUE())) -> 0 | G5: =IF($A5<=0,0,0.125*_xlfn.NORM.S.DIST((LN($A5)-データ!$G$5)/データ!$G$10,TRUE())+0.25*_xlfn.NORM.S.DIST((LN($A5)-データ!$G$6)/データ!$G$10,TRUE())+0.25*_xlfn.NORM.S.DIST((LN($A5)-データ!$G$7)/データ!$G$10,TRUE())+0.25*_xlfn.NORM.S.DIST((LN($A5)-データ!$G$8)/データ!$G$10,TRUE())+0.125*_xlfn.NORM.S.DIST((LN($A5)-データ!$G$9)/データ!$G$10,TRUE())) -> 0
A6: 10 | B6: =IF($A6<=0,0,0.125*_xlfn.NORM.S.DIST((LN($A6)-データ!$B$5)/データ!$B$10,TRUE())+0.25*_xlfn.NORM.S.DIST((LN($A6)-データ!$B$6)/データ!$B$10,TRUE())+0.375*_xlfn.NORM.S.DIST((LN($A6)-データ!$B$7)/データ!$B$10,TRUE())) -> 0.021181666 | C6: =IF($A6<=0,0,0.125*_xlfn.NORM.S.DIST((LN($A6)-データ!$C$5)/データ!$C$10,TRUE())+0.25*_xlfn.NORM.S.DIST((LN($A6)-データ!$C$6)/データ!$C$10,TRUE())+0.375*_xlfn.NORM.S.DIST((LN($A6)-データ!$C$7)/データ!$C$10,TRUE())) -> 0.016682103 | D6: =IF($A6<=0,0,0.125*_xlfn.NORM.S.DIST((LN($A6)-データ!$D$5)/データ!$D$10,TRUE())+0.25*_xlfn.NORM.S.DIST((LN($A6)-データ!$D$6)/データ!$D$10,TRUE())+0.375*_xlfn.NORM.S.DIST((LN($A6)-データ!$D$7)/データ!$D$10,TRUE())) -> 0.038891981 | E6: =IF($A6<=0,0,0.125*_xlfn.NORM.S.DIST((LN($A6)-データ!$E$5)/データ!$E$10,TRUE())+0.25*_xlfn.NORM.S.DIST((LN($A6)-データ!$E$6)/データ!$E$10,TRUE())+0.25*_xlfn.NORM.S.DIST((LN($A6)-データ!$E$7)/データ!$E$10,TRUE())+0.25*_xlfn.NORM.S.DIST((LN($A6)-データ!$E$8)/データ!$E$10,TRUE())+0.125*_xlfn.NORM.S.DIST((LN($A6)-データ!$E$9)/データ!$E$10,TRUE())) -> 0.071486095 | F6: =IF($A6<=0,0,0.125*_xlfn.NORM.S.DIST((LN($A6)-データ!$F$5)/データ!$F$10,TRUE())+0.25*_xlfn.NORM.S.DIST((LN($A6)-データ!$F$6)/データ!$F$10,TRUE())+0.25*_xlfn.NORM.S.DIST((LN($A6)-データ!$F$7)/データ!$F$10,TRUE())+0.25*_xlfn.NORM.S.DIST((LN($A6)-データ!$F$8)/データ!$F$10,TRUE())+0.125*_xlfn.NORM.S.DIST((LN($A6)-データ!$F$9)/データ!$F$10,TRUE())) -> 0.11488358 | G6: =IF($A6<=0,0,0.125*_xlfn.NORM.S.DIST((LN($A6)-データ!$G$5)/データ!$G$10,TRUE())+0.25*_xlfn.NORM.S.DIST((LN($A6)-データ!$G$6)/データ!$G$10,TRUE())+0.25*_xlfn.NORM.S.DIST((LN($A6)-データ!$G$7)/データ!$G$10,TRUE())+0.25*_xlfn.NORM.S.DIST((LN($A6)-データ!$G$8)/データ!$G$10,TRUE())+0.125*_xlfn.NORM.S.DIST((LN($A6)-データ!$G$9)/データ!$G$10,TRUE())) -> 0.18596702
A7: 20 | B7: =IF($A7<=0,0,0.125*_xlfn.NORM.S.DIST((LN($A7)-データ!$B$5)/データ!$B$10,TRUE())+0.25*_xlfn.NORM.S.DIST((LN($A7)-データ!$B$6)/データ!$B$10,TRUE())+0.375*_xlfn.NORM.S.DIST((LN($A7)-データ!$B$7)/データ!$B$10,TRUE())) -> 0.055792201 | C7: =IF($A7<=0,0,0.125*_xlfn.NORM.S.DIST((LN($A7)-データ!$C$5)/データ!$C$10,TRUE())+0.25*_xlfn.NORM.S.DIST((LN($A7)-データ!$C$6)/データ!$C$10,TRUE())+0.375*_xlfn.NORM.S.DIST((LN($A7)-データ!$C$7)/データ!$C$10,TRUE())) -> 0.046150089 | D7: =IF($A7<=0,0,0.125*_xlfn.NORM.S.DIST((LN($A7)-データ!$D$5)/データ!$D$10,TRUE())+0.25*_xlfn.NORM.S.DIST((LN($A7)-データ!$D$6)/データ!$D$10,TRUE())+0.375*_xlfn.NORM.S.DIST((LN($A7)-データ!$D$7)/データ!$D$10,TRUE())) -> 0.08115607 | E7: =IF($A7<=0,0,0.125*_xlfn.NORM.S.DIST((LN($A7)-データ!$E$5)/データ!$E$10,TRUE())+0.25*_xlfn.NORM.S.DIST((LN($A7)-データ!$E$6)/データ!$E$10,TRUE())+0.25*_xlfn.NORM.S.DIST((LN($A7)-データ!$E$7)/データ!$E$10,TRUE())+0.25*_xlfn.NORM.S.DIST((LN($A7)-データ!$E$8)/データ!$E$10,TRUE())+0.125*_xlfn.NORM.S.DIST((LN($A7)-データ!$E$9)/データ!$E$10,TRUE())) -> 0.11524519 | F7: =IF($A7<=0,0,0.125*_xlfn.NORM.S.DIST((LN($A7)-データ!$F$5)/データ!$F$10,TRUE())+0.25*_xlfn.NORM.S.DIST((LN($A7)-データ!$F$6)/データ!$F$10,TRUE())+0.25*_xlfn.NORM.S.DIST((LN($A7)-データ!$F$7)/データ!$F$10,TRUE())+0.25*_xlfn.NORM.S.DIST((LN($A7)-データ!$F$8)/データ!$F$10,TRUE())+0.125*_xlfn.NORM.S.DIST((LN($A7)-データ!$F$9)/データ!$F$10,TRUE())) -> 0.18748369 | G7: =IF($A7<=0,0,0.125*_xlfn.NORM.S.DIST((LN($A7)-データ!$G$5)/データ!$G$10,TRUE())+0.25*_xlfn.NORM.S.DIST((LN($A7)-データ!$G$6)/データ!$G$10,TRUE())+0.25*_xlfn.NORM.S.DIST((LN($A7)-データ!$G$7)/データ!$G$10,TRUE())+0.25*_xlfn.NORM.S.DIST((LN($A7)-データ!$G$8)/データ!$G$10,TRUE())+0.125*_xlfn.NORM.S.DIST((LN($A7)-データ!$G$9)/データ!$G$10,TRUE())) -> 0.23456337
A8: 30 | B8: =IF($A8<=0,0,0.125*_xlfn.NORM.S.DIST((LN($A8)-データ!$B$5)/データ!$B$10,TRUE())+0.25*_xlfn.NORM.S.DIST((LN($A8)-データ!$B$6)/データ!$B$10,TRUE())+0.375*_xlfn.NORM.S.DIST((LN($A8)-データ!$B$7)/データ!$B$10,TRUE())) -> 0.083638324 | C8: =IF($A8<=0,0,0.125*_xlfn.NORM.S.DIST((LN($A8)-データ!$C$5)/データ!$C$10,TRUE())+0.25*_xlfn.NORM.S.DIST((LN($A8)-データ!$C$6)/データ!$C$10,TRUE())+0.375*_xlfn.NORM.S.DIST((LN($A8)-データ!$C$7)/データ!$C$10,TRUE())) -> 0.074144141 | D8: =IF($A8<=0,0,0.125*_xlfn.NORM.S.DIST((LN($A8)-データ!$D$5)/データ!$D$10,TRUE())+0.25*_xlfn.NORM.S.DIST((LN($A8)-データ!$D$6)/データ!$D$10,TRUE())+0.375*_xlfn.NORM.S.DIST((LN($A8)-データ!$D$7)/データ!$D$10,TRUE())) -> 0.10795271 | E8: =IF($A8<=0,0,0.125*_xlfn.NORM.S.DIST((LN($A8)-データ!$E$5)/データ!$E$10,TRUE())+0.25*_xlfn.NORM.S.DIST((LN($A8)-データ!$E$6)/データ!$E$10,TRUE())+0.25*_xlfn.NORM.S.DIST((LN($A8)-データ!$E$7)/データ!$E$10,TRUE())+0.25*_xlfn.NORM.S.DIST((LN($A8)-データ!$E$8)/データ!$E$10,TRUE())+0.125*_xlfn.NORM.S.DIST((LN($A8)-データ!$E$9)/データ!$E$10,TRUE())) -> 0.14857334 | F8: =IF($A8<=0,0,0.125*_xlfn.NORM.S.DIST((LN($A8)-データ!$F$5)/データ!$F$10,TRUE())+0.25*_xlfn.NORM.S.DIST((LN($A8)-データ!$F$6)/データ!$F$10,TRUE())+0.25*_xlfn.NORM.S.DIST((LN($A8)-データ!$F$7)/データ!$F$10,TRUE())+0.25*_xlfn.NORM.S.DIST((LN($A8)-データ!$F$8)/データ!$F$10,TRUE())+0.125*_xlfn.NORM.S.DIST((LN($A8)-データ!$F$9)/データ!$F$10,TRUE())) -> 0.24268147 | G8: =IF($A8<=0,0,0.125*_xlfn.NORM.S.DIST((LN($A8)-データ!$G$5)/データ!$G$10,TRUE())+0.25*_xlfn.NORM.S.DIST((LN($A8)-データ!$G$6)/データ!$G$10,TRUE())+0.25*_xlfn.NORM.S.DIST((LN($A8)-データ!$G$7)/データ!$G$10,TRUE())+0.25*_xlfn.NORM.S.DIST((LN($A8)-データ!$G$8)/データ!$G$10,TRUE())+0.125*_xlfn.NORM.S.DIST((LN($A8)-データ!$G$9)/データ!$G$10,TRUE())) -> 0.26739572
A9: 40 | B9: =IF($A9<=0,0,0.125*_xlfn.NORM.S.DIST((LN($A9)-データ!$B$5)/データ!$B$10,TRUE())+0.25*_xlfn.NORM.S.DIST((LN($A9)-データ!$B$6)/データ!$B$10,TRUE())+0.375*_xlfn.NORM.S.DIST((LN($A9)-データ!$B$7)/データ!$B$10,TRUE())) -> 0.10645244 | C9: =IF($A9<=0,0,0.125*_xlfn.NORM.S.DIST((LN($A9)-データ!$C$5)/データ!$C$10,TRUE())+0.25*_xlfn.NORM.S.DIST((LN($A9)-データ!$C$6)/データ!$C$10,TRUE())+0.375*_xlfn.NORM.S.DIST((LN($A9)-データ!$C$7)/データ!$C$10,TRUE())) -> 0.099443525 | D9: =IF($A9<=0,0,0.125*_xlfn.NORM.S.DIST((LN($A9)-データ!$D$5)/データ!$D$10,TRUE())+0.25*_xlfn.NORM.S.DIST((LN($A9)-データ!$D$6)/データ!$D$10,TRUE())+0.375*_xlfn.NORM.S.DIST((LN($A9)-データ!$D$7)/データ!$D$10,TRUE())) -> 0.12905714 | E9: =IF($A9<=0,0,0.125*_xlfn.NORM.S.DIST((LN($A9)-データ!$E$5)/データ!$E$10,TRUE())+0.25*_xlfn.NORM.S.DIST((LN($A9)-データ!$E$6)/データ!$E$10,TRUE())+0.25*_xlfn.NORM.S.DIST((LN($A9)-データ!$E$7)/データ!$E$10,TRUE())+0.25*_xlfn.NORM.S.DIST((LN($A9)-データ!$E$8)/データ!$E$10,TRUE())+0.125*_xlfn.NORM.S.DIST((LN($A9)-データ!$E$9)/データ!$E$10,TRUE())) -> 0.17719584 | F9: =IF($A9<=0,0,0.125*_xlfn.NORM.S.DIST((LN($A9)-データ!$F$5)/データ!$F$10,TRUE())+0.25*_xlfn.NORM.S.DIST((LN($A9)-データ!$F$6)/データ!$F$10,TRUE())+0.25*_xlfn.NORM.S.DIST((LN($A9)-データ!$F$7)/データ!$F$10,TRUE())+0.25*_xlfn.NORM.S.DIST((LN($A9)-データ!$F$8)/データ!$F$10,TRUE())+0.125*_xlfn.NORM.S.DIST((LN($A9)-データ!$F$9)/データ!$F$10,TRUE())) -> 0.28782014 | G9: =IF($A9<=0,0,0.125*_xlfn.NORM.S.DIST((LN($A9)-データ!$G$5)/データ!$G$10,TRUE())+0.25*_xlfn.NORM.S.DIST((LN($A9)-データ!$G$6)/データ!$G$10,TRUE())+0.25*_xlfn.NORM.S.DIST((LN($A9)-データ!$G$7)/データ!$G$10,TRUE())+0.25*_xlfn.NORM.S.DIST((LN($A9)-データ!$G$8)/データ!$G$10,TRUE())+0.125*_xlfn.NORM.S.DIST((LN($A9)-データ!$G$9)/データ!$G$10,TRUE())) -> 0.29269893
